Workbook
Name FAOCODES: FAO!$B$1:$W$1

Sheet M-01
G1: =FAO!B1&" max =" | H1: =+FAO!B10 | J1: =FAO!E1&" max =" | K1: =+FAO!E10 | M1: =FAO!H1&" max =" | N1: =+FAO!H10 | P1: =FAO!K1&" max =" | Q1: =+FAO!K10 | S1: =FAO!N1&" max =" | T1: =+FAO!N10 | V1: =FAO!Q1&" max =" | W1: =+FAO!Q10 | Y1: =FAO!T1&" max =" | Z1: =+FAO!T10 | AB1: =FAO!W1&" max =" | AC1: =+FAO!W10
G2: obs n = | H2: =COUNTIF($C$15:$C$1003,G13) | J2: obs n = | K2: =COUNTIF($C$15:$C$1003,J13) | M2: obs n = | N2: =COUNTIF($C$15:$C$1003,M13) | P2: obs n = | Q2: =COUNTIF($C$15:$C$1003,P13) | S2: obs n = | T2: =COUNTIF($C$15:$C$1003,S13) | V2: obs n = | W2: =COUNTIF($C$15:$C$1003,V13) | Y2: obs n = | Z2: =COUNTIF($C$15:$C$1003,Y13) | AB2: obs n = | AC2: =COUNTIF($C$15:$C$1003,AB13)
G3: freq n= | H3: =+SUM(H15:H1003) | J3: freq n= | K3: =+SUM(K15:K1003) | M3: freq n= | N3: =+SUM(N15:N1003) | P3: freq n= | Q3: =+SUM(Q15:Q1003) | S3: freq n= | T3: =+SUM(T15:T1003) | V3: freq n= | W3: =+SUM(W15:W1003) | Y3: freq n= | Z3: =+SUM(Z15:Z1003) | AB3: freq n= | AC3: =+SUM(AC15:AC1003)
G4: first bin = | H4: 10 | J4: first bin = | K4: 10 | M4: first bin = | N4: 10 | P4: first bin = | Q4: 10 | S4: first bin = | T4: 10 | V4: first bin = | W4: 10 | Y4: first bin = | Z4: 10 | AB4: first bin = | AC4: 10
G5: increment = | H5: =+FAO!B14 | J5: increment = | K5: =+FAO!E14 | M5: increment = | N5: =+FAO!H14 | P5: increment = | Q5: =+FAO!K14 | S5: increment = | T5: =+FAO!N14 | V5: increment = | W5: =+FAO!Q14 | Y5: increment = | Z5: =+FAO!T14 | AB5: increment = | AC5: =+FAO!W14
G6: Complete = | H6: =COUNTIFS($C$15:$C$2015,G$13,$D$15:$D$2015,">5")/COUNTIF($C$15:$C$2015,G$13)*100 | J6: Complete = | K6: =COUNTIFS($C$15:$C$2015,J$13,$D$15:$D$2015,">5")/COUNTIF($C$15:$C$2015,J$13)*100 | M6: Complete = | N6: =COUNTIFS($C$15:$C$2015,M$13,$D$15:$D$2015,">5")/COUNTIF($C$15:$C$2015,M$13)*100 | P6: Complete = | Q6: =COUNTIFS($C$15:$C$2015,P$13,$D$15:$D$2015,">5")/COUNTIF($C$15:$C$2015,P$13)*100 | S6: Complete = | T6: =COUNTIFS($C$15:$C$2015,S$13,$D$15:$D$2015,">5")/COUNTIF($C$15:$C$2015,S$13)*100 | V6: Complete = | W6: =COUNTIFS($C$15:$C$2015,V$13,$D$15:$D$2015,">5")/COUNTIF($C$15:$C$2015,V$13)*100 | Y6: Complete = | Z6: =COUNTIFS($C$15:$C$2015,Y$13,$D$15:$D$2015,">5")/COUNTIF($C$15:$C$2015,Y$13)*100 | AB6: Complete = | AC6: =COUNTIFS($C$15:$C$2015,AB$13,$D$15:$D$2015,">5")/COUNTIF($C$15:$C$2015,AB$13)*100
G7: L50 (cm) = | H7: =+FAO!B11 | J7: L50 (cm) = | K7: =+FAO!E11 | M7: L50 (cm) = | N7: =+FAO!H11 | P7: L50 (cm) = | Q7: =+FAO!K11 | S7: L50 (cm) = | T7: =+FAO!N11 | V7: L50 (cm) = | W7: =+FAO!Q11 | Y7: L50 (cm) = | Z7: =+FAO!T11 | AB7: L50 (cm) = | AC7: =+FAO!W11
G8: Juven. (%) = | H8: =+ROUND(COUNTIFS($C$15:$C$2015,G$13,$D$15:$D$2015,"<"&H7)/COUNTIF($C$15:$C$2015,G$13)*100,0) | J8: Juven. (%) = | K8: =+ROUND(COUNTIFS($C$15:$C$2015,J$13,$D$15:$D$2015,"<"&K7)/COUNTIF($C$15:$C$2015,J$13)*100,0) | M8: Juven. (%) = | N8: =+ROUND(COUNTIFS($C$15:$C$2015,M$13,$D$15:$D$2015,"<"&N7)/COUNTIF($C$15:$C$2015,M$13)*100,0) | P8: Juven. (%) = | Q8: =+ROUND(COUNTIFS($C$15:$C$2015,P$13,$D$15:$D$2015,"<"&Q7)/COUNTIF($C$15:$C$2015,P$13)*100,0) | S8: Juven. (%) = | T8: =+ROUND(COUNTIFS($C$15:$C$2015,S$13,$D$15:$D$2015,"<"&T7)/COUNTIF($C$15:$C$2015,S$13)*100,0) | V8: Juven. (%) = | W8: =+ROUND(COUNTIFS($C$15:$C$2015,V$13,$D$15:$D$2015,"<"&W7)/COUNTIF($C$15:$C$2015,V$13)*100,0) | Y8: Juven. (%) = | Z8: =+ROUND(COUNTIFS($C$15:$C$2015,Y$13,$D$15:$D$2015,"<"&Z7)/COUNTIF($C$15:$C$2015,Y$13)*100,0) | AB8: Juven. (%) = | AC8: =+ROUND(COUNTIFS($C$15:$C$2015,AB$13,$D$15:$D$2015,"<"&AC7)/COUNTIF($C$15:$C$2015,AB$13)*100,0)
G9: =+FAO!B6 | J9: =+FAO!E6 | M9: =+FAO!H6 | P9: =+FAO!K6 | S9: =+FAO!N6 | V9: =+FAO!Q6 | Y9: =+FAO!T6 | AB9: =+FAO!W6
G10: =+FAO!B7 | J10: =+FAO!E7 | M10: =+FAO!H7 | P10: =+FAO!K7 | S10: =+FAO!N7 | V10: =+FAO!Q7 | Y10: =+FAO!T7 | AB10: =+FAO!W7
G11: =+FAO!B9 | J11: =+FAO!E9 | M11: =+FAO!H9 | P11: =+FAO!K9 | S11: =+FAO!N9 | V11: =+FAO!Q9 | Y11: =+FAO!T9 | AB11: =+FAO!W9
G12: =+FAO!B5 | J12: =+FAO!E5 | M12: =+FAO!H5 | P12: =+FAO!K5 | S12: =+FAO!N5 | V12: =+FAO!Q5 | Y12: =+FAO!T5 | AB12: =+FAO!W5
D13: #VALUE! | E13: =COUNTA(C15:C1003) | G13: =+FAO!B1 | H13: =+FAO!B3 | J13: =+FAO!E1 | K13: =+FAO!E3 | M13: =+FAO!H1 | N13: =+FAO!H3 | P13: =+FAO!K1 | Q13: =+FAO!K3 | S13: =+FAO!N1 | T13: =+FAO!N3 | V13: =+FAO!Q1 | W13: =+FAO!Q3 | Y13: =+FAO!T1 | Z13: =+FAO!T3 | AB13: =+FAO!W1 | AC13: =+FAO!W3
A14: TRIP | B14: DATE | C14: FAO | D14: OBS | E14: ID | G14: ="LC-"&G13 | H14: ="FQ-"&G13 | J14: ="LC-"&J13 | K14: ="FQ-"&J13 | M14: ="LC-"&M13 | N14: ="FQ-"&M13 | P14: ="LC-"&P13 | Q14: ="FQ-"&P13 | S14: ="LC-"&S13 | T14: ="FQ-"&S13 | V14: ="LC-"&V13 | W14: ="FQ-"&V13 | Y14: ="LC-"&Y13 | Z14: ="FQ-"&Y13 | AB14: ="LC-"&AB13 | AC14: ="FQ-"&AB13
C15: LTQ | D15: 78 | E15: {=+_xlfn.SEQUENCE(E13,1,1)} | G15: {=_xlfn.SEQUENCE(((H1-H4)/H5)+1, 1, H4, H5)} | H15: =IF(G15="","",COUNTIFS($C$15:$C$2015,G$13,$D$15:$D$2015,">="&G15,$D$15:$D$2015,"<"&G16)) | J15: {=_xlfn.SEQUENCE(((K1-K4)/K5)+1, 1, K4, K5)} | K15: =IF(J15="","",COUNTIFS($C$15:$C$2015,J$13,$D$15:$D$2015,">="&J15,$D$15:$D$2015,"<"&J16)) | M15: {=_xlfn.SEQUENCE(((N1-N4)/N5)+1, 1, N4, N5)} | N15: =IF(M15="","",COUNTIFS($C$15:$C$2015,M$13,$D$15:$D$2015,">="&M15,$D$15:$D$2015,"<"&M16)) | P15: {=_xlfn.SEQUENCE(((Q1-Q4)/Q5)+1, 1, Q4, Q5)} | Q15: =IF(P15="","",COUNTIFS($C$15:$C$2015,P$13,$D$15:$D$2015,">="&P15,$D$15:$D$2015,"<"&P16)) | S15: {=_xlfn.SEQUENCE(((T1-T4)/T5)+1, 1, T4, T5)} | T15: =IF(S15="","",COUNTIFS($C$15:$C$2015,S$13,$D$15:$D$2015,">="&S15,$D$15:$D$2015,"<"&S16)) | V15: {=_xlfn.SEQUENCE(((W1-W4)/W5)+1, 1, W4, W5)} | W15: =IF(V15="","",COUNTIFS($C$15:$C$2015,V$13,$D$15:$D$2015,">="&V15,$D$15:$D$2015,"<"&V16)) | Y15: {=_xlfn.SEQUENCE(((Z1-Z4)/Z5)+1, 1, Z4, Z5)} | Z15: =IF(Y15="","",COUNTIFS($C$15:$C$2015,Y$13,$D$15:$D$2015,">="&Y15,$D$15:$D$2015,"<"&Y16)) | AB15: {=_xlfn.SEQUENCE(((AC1-AC4)/AC5)+1, 1, AC4, AC5)} | AC15: =IF(AB15="","",COUNTIFS($C$15:$C$2015,AB$13,$D$15:$D$2015,">="&AB15,$D$15:$D$2015,"<"&AB16))
C16: COM | D16: 145 | E16: 2 | G16: 11 | H16: =IF(G16="","",COUNTIFS($C$15:$C$2015,G$13,$D$15:$D$2015,">="&G16,$D$15:$D$2015,"<"&G17)) | J16: 15 | K16: =IF(J16="","",COUNTIFS($C$15:$C$2015,J$13,$D$15:$D$2015,">="&J16,$D$15:$D$2015,"<"&J17)) | M16: 12 | N16: =IF(M16="","",COUNTIFS($C$15:$C$2015,M$13,$D$15:$D$2015,">="&M16,$D$15:$D$2015,"<"&M17)) | P16: 11 | Q16: =IF(P16="","",COUNTIFS($C$15:$C$2015,P$13,$D$15:$D$2015,">="&P16,$D$15:$D$2015,"<"&P17)) | S16: 12 | T16: =IF(S16="","",COUNTIFS($C$15:$C$2015,S$13,$D$15:$D$2015,">="&S16,$D$15:$D$2015,"<"&S17)) | V16: 12 | W16: =IF(V16="","",COUNTIFS($C$15:$C$2015,V$13,$D$15:$D$2015,">="&V16,$D$15:$D$2015,"<"&V17)) | Y16: 12 | Z16: =IF(Y16="","",COUNTIFS($C$15:$C$2015,Y$13,$D$15:$D$2015,">="&Y16,$D$15:$D$2015,"<"&Y17)) | AB16: 11 | AC16: =IF(AB16="","",COUNTIFS($C$15:$C$2015,AB$13,$D$15:$D$2015,">="&AB16,$D$15:$D$2015,"<"&AB17))
C17: LJB | D17: 88 | E17: 3 | G17: 12 | H17: =IF(G17="","",COUNTIFS($C$15:$C$2015,G$13,$D$15:$D$2015,">="&G17,$D$15:$D$2015,"<"&G18)) | J17: 20 | K17: =IF(J17="","",COUNTIFS($C$15:$C$2015,J$13,$D$15:$D$2015,">="&J17,$D$15:$D$2015,"<"&J18)) | M17: 14 | N17: =IF(M17="","",COUNTIFS($C$15:$C$2015,M$13,$D$15:$D$2015,">="&M17,$D$15:$D$2015,"<"&M18)) | P17: 12 | Q17: =IF(P17="","",COUNTIFS($C$15:$C$2015,P$13,$D$15:$D$2015,">="&P17,$D$15:$D$2015,"<"&P18)) | S17: 14 | T17: =IF(S17="","",COUNTIFS($C$15:$C$2015,S$13,$D$15:$D$2015,">="&S17,$D$15:$D$2015,"<"&S18)) | V17: 14 | W17: =IF(V17="","",COUNTIFS($C$15:$C$2015,V$13,$D$15:$D$2015,">="&V17,$D$15:$D$2015,"<"&V18)) | Y17: 14 | Z17: =IF(Y17="","",COUNTIFS($C$15:$C$2015,Y$13,$D$15:$D$2015,">="&Y17,$D$15:$D$2015,"<"&Y18)) | AB17: 12 | AC17: =IF(AB17="","",COUNTIFS($C$15:$C$2015,AB$13,$D$15:$D$2015,">="&AB17,$D$15:$D$2015,"<"&AB18))
C18: EWS | D18: 79 | E18: 4 | G18: 13 | H18: =IF(G18="","",COUNTIFS($C$15:$C$2015,G$13,$D$15:$D$2015,">="&G18,$D$15:$D$2015,"<"&G19)) | J18: 25 | K18: =IF(J18="","",COUNTIFS($C$15:$C$2015,J$13,$D$15:$D$2015,">="&J18,$D$15:$D$2015,"<"&J19)) | M18: 16 | N18: =IF(M18="","",COUNTIFS($C$15:$C$2015,M$13,$D$15:$D$2015,">="&M18,$D$15:$D$2015,"<"&M19)) | P18: 13 | Q18: =IF(P18="","",COUNTIFS($C$15:$C$2015,P$13,$D$15:$D$2015,">="&P18,$D$15:$D$2015,"<"&P19)) | S18: 16 | T18: =IF(S18="","",COUNTIFS($C$15:$C$2015,S$13,$D$15:$D$2015,">="&S18,$D$15:$D$2015,"<"&S19)) | V18: 16 | W18: =IF(V18="","",COUNTIFS($C$15:$C$2015,V$13,$D$15:$D$2015,">="&V18,$D$15:$D$2015,"<"&V19)) | Y18: 16 | Z18: =IF(Y18="","",COUNTIFS($C$15:$C$2015,Y$13,$D$15:$D$2015,">="&Y18,$D$15:$D$2015,"<"&Y19)) | AB18: 13 | AC18: =IF(AB18="","",COUNTIFS($C$15:$C$2015,AB$13,$D$15:$D$2015,">="&AB18,$D$15:$D$2015,"<"&AB19))
C19: KAW | D19: 99 | E19: 5 | G19: 14 | H19: =IF(G19="","",COUNTIFS($C$15:$C$2015,G$13,$D$15:$D$2015,">="&G19,$D$15:$D$2015,"<"&G20)) | J19: 30 | K19: =IF(J19="","",COUNTIFS($C$15:$C$2015,J$13,$D$15:$D$2015,">="&J19,$D$15:$D$2015,"<"&J20)) | M19: 18 | N19: =IF(M19="","",COUNTIFS($C$15:$C$2015,M$13,$D$15:$D$2015,">="&M19,$D$15:$D$2015,"<"&M20)) | P19: 14 | Q19: =IF(P19="","",COUNTIFS($C$15:$C$2015,P$13,$D$15:$D$2015,">="&P19,$D$15:$D$2015,"<"&P20)) | S19: 18 | T19: =IF(S19="","",COUNTIFS($C$15:$C$2015,S$13,$D$15:$D$2015,">="&S19,$D$15:$D$2015,"<"&S20)) | V19: 18 | W19: =IF(V19="","",COUNTIFS($C$15:$C$2015,V$13,$D$15:$D$2015,">="&V19,$D$15:$D$2015,"<"&V20)) | Y19: 18 | Z19: =IF(Y19="","",COUNTIFS($C$15:$C$2015,Y$13,$D$15:$D$2015,">="&Y19,$D$15:$D$2015,"<"&Y20)) | AB19: 14 | AC19: =IF(AB19="","",COUNTIFS($C$15:$C$2015,AB$13,$D$15:$D$2015,">="&AB19,$D$15:$D$2015,"<"&AB20))
C20: EMU | D20: 79 | E20: 6 | G20: 15 | H20: =IF(G20="","",COUNTIFS($C$15:$C$2015,G$13,$D$15:$D$2015,">="&G20,$D$15:$D$2015,"<"&G21)) | J20: 35 | K20: =IF(J20="","",COUNTIFS($C$15:$C$2015,J$13,$D$15:$D$2015,">="&J20,$D$15:$D$2015,"<"&J21)) | M20: 20 | N20: =IF(M20="","",COUNTIFS($C$15:$C$2015,M$13,$D$15:$D$2015,">="&M20,$D$15:$D$2015,"<"&M21)) | P20: 15 | Q20: =IF(P20="","",COUNTIFS($C$15:$C$2015,P$13,$D$15:$D$2015,">="&P20,$D$15:$D$2015,"<"&P21)) | S20: 20 | T20: =IF(S20="","",COUNTIFS($C$15:$C$2015,S$13,$D$15:$D$2015,">="&S20,$D$15:$D$2015,"<"&S21)) | V20: 20 | W20: =IF(V20="","",COUNTIFS($C$15:$C$2015,V$13,$D$15:$D$2015,">="&V20,$D$15:$D$2015,"<"&V21)) | Y20: 20 | Z20: =IF(Y20="","",COUNTIFS($C$15:$C$2015,Y$13,$D$15:$D$2015,">="&Y20,$D$15:$D$2015,"<"&Y21)) | AB20: 15 | AC20: =IF(AB20="","",COUNTIFS($C$15:$C$2015,AB$13,$D$15:$D$2015,">="&AB20,$D$15:$D$2015,"<"&AB21))
C21: EME | D21: 79 | E21: 7 | G21: 16 | H21: =IF(G21="","",COUNTIFS($C$15:$C$2015,G$13,$D$15:$D$2015,">="&G21,$D$15:$D$2015,"<"&G22)) | J21: 40 | K21: =IF(J21="","",COUNTIFS($C$15:$C$2015,J$13,$D$15:$D$2015,">="&J21,$D$15:$D$2015,"<"&J22)) | M21: 22 | N21: =IF(M21="","",COUNTIFS($C$15:$C$2015,M$13,$D$15:$D$2015,">="&M21,$D$15:$D$2015,"<"&M22)) | P21: 16 | Q21: =IF(P21="","",COUNTIFS($C$15:$C$2015,P$13,$D$15:$D$2015,">="&P21,$D$15:$D$2015,"<"&P22)) | S21: 22 | T21: =IF(S21="","",COUNTIFS($C$15:$C$2015,S$13,$D$15:$D$2015,">="&S21,$D$15:$D$2015,"<"&S22)) | V21: 22 | W21: =IF(V21="","",COUNTIFS($C$15:$C$2015,V$13,$D$15:$D$2015,">="&V21,$D$15:$D$2015,"<"&V22)) | Y21: 22 | Z21: =IF(Y21="","",COUNTIFS($C$15:$C$2015,Y$13,$D$15:$D$2015,">="&Y21,$D$15:$D$2015,"<"&Y22)) | AB21: 16 | AC21: =IF(AB21="","",COUNTIFS($C$15:$C$2015,AB$13,$D$15:$D$2015,">="&AB21,$D$15:$D$2015,"<"&AB22))
C22: VRL | D22: 61 | E22: 8 | G22: 17 | H22: =IF(G22="","",COUNTIFS($C$15:$C$2015,G$13,$D$15:$D$2015,">="&G22,$D$15:$D$2015,"<"&G23)) | J22: 45 | K22: =IF(J22="","",COUNTIFS($C$15:$C$2015,J$13,$D$15:$D$2015,">="&J22,$D$15:$D$2015,"<"&J23)) | M22: 24 | N22: =IF(M22="","",COUNTIFS($C$15:$C$2015,M$13,$D$15:$D$2015,">="&M22,$D$15:$D$2015,"<"&M23)) | P22: 17 | Q22: =IF(P22="","",COUNTIFS($C$15:$C$2015,P$13,$D$15:$D$2015,">="&P22,$D$15:$D$2015,"<"&P23)) | S22: 24 | T22: =IF(S22="","",COUNTIFS($C$15:$C$2015,S$13,$D$15:$D$2015,">="&S22,$D$15:$D$2015,"<"&S23)) | V22: 24 | W22: =IF(V22="","",COUNTIFS($C$15:$C$2015,V$13,$D$15:$D$2015,">="&V22,$D$15:$D$2015,"<"&V23)) | Y22: 24 | Z22: =IF(Y22="","",COUNTIFS($C$15:$C$2015,Y$13,$D$15:$D$2015,">="&Y22,$D$15:$D$2015,"<"&Y23)) | AB22: 17 | AC22: =IF(AB22="","",COUNTIFS($C$15:$C$2015,AB$13,$D$15:$D$2015,">="&AB22,$D$15:$D$2015,"<"&AB23))
C23: LTQ | D23: 9 | E23: 9 | G23: 18 | H23: =IF(G23="","",COUNTIFS($C$15:$C$2015,G$13,$D$15:$D$2015,">="&G23,$D$15:$D$2015,"<"&G24)) | J23: 50 | K23: =IF(J23="","",COUNTIFS($C$15:$C$2015,J$13,$D$15:$D$2015,">="&J23,$D$15:$D$2015,"<"&J24)) | M23: 26 | N23: =IF(M23="","",COUNTIFS($C$15:$C$2015,M$13,$D$15:$D$2015,">="&M23,$D$15:$D$2015,"<"&M24)) | P23: 18 | Q23: =IF(P23="","",COUNTIFS($C$15:$C$2015,P$13,$D$15:$D$2015,">="&P23,$D$15:$D$2015,"<"&P24)) | S23: 26 | T23: =IF(S23="","",COUNTIFS($C$15:$C$2015,S$13,$D$15:$D$2015,">="&S23,$D$15:$D$2015,"<"&S24)) | V23: 26 | W23: =IF(V23="","",COUNTIFS($C$15:$C$2015,V$13,$D$15:$D$2015,">="&V23,$D$15:$D$2015,"<"&V24)) | Y23: 26 | Z23: =IF(Y23="","",COUNTIFS($C$15:$C$2015,Y$13,$D$15:$D$2015,">="&Y23,$D$15:$D$2015,"<"&Y24)) | AB23: 18 | AC23: =IF(AB23="","",COUNTIFS($C$15:$C$2015,AB$13,$D$15:$D$2015,">="&AB23,$D$15:$D$2015,"<"&AB24))
C24: COM | D24: 9 | E24: 10 | G24: 19 | H24: =IF(G24="","",COUNTIFS($C$15:$C$2015,G$13,$D$15:$D$2015,">="&G24,$D$15:$D$2015,"<"&G25)) | J24: 55 | K24: =IF(J24="","",COUNTIFS($C$15:$C$2015,J$13,$D$15:$D$2015,">="&J24,$D$15:$D$2015,"<"&J25)) | M24: 28 | N24: =IF(M24="","",COUNTIFS($C$15:$C$2015,M$13,$D$15:$D$2015,">="&M24,$D$15:$D$2015,"<"&M25)) | P24: 19 | Q24: =IF(P24="","",COUNTIFS($C$15:$C$2015,P$13,$D$15:$D$2015,">="&P24,$D$15:$D$2015,"<"&P25)) | S24: 28 | T24: =IF(S24="","",COUNTIFS($C$15:$C$2015,S$13,$D$15:$D$2015,">="&S24,$D$15:$D$2015,"<"&S25)) | V24: 28 | W24: =IF(V24="","",COUNTIFS($C$15:$C$2015,V$13,$D$15:$D$2015,">="&V24,$D$15:$D$2015,"<"&V25)) | Y24: 28 | Z24: =IF(Y24="","",COUNTIFS($C$15:$C$2015,Y$13,$D$15:$D$2015,">="&Y24,$D$15:$D$2015,"<"&Y25)) | AB24: 19 | AC24: =IF(AB24="","",COUNTIFS($C$15:$C$2015,AB$13,$D$15:$D$2015,">="&AB24,$D$15:$D$2015,"<"&AB25))
C25: LJB | D25: 9 | E25: 11 | G25: 20 | H25: =IF(G25="","",COUNTIFS($C$15:$C$2015,G$13,$D$15:$D$2015,">="&G25,$D$15:$D$2015,"<"&G26)) | J25: 60 | K25: =IF(J25="","",COUNTIFS($C$15:$C$2015,J$13,$D$15:$D$2015,">="&J25,$D$15:$D$2015,"<"&J26)) | M25: 30 | N25: =IF(M25="","",COUNTIFS($C$15:$C$2015,M$13,$D$15:$D$2015,">="&M25,$D$15:$D$2015,"<"&M26)) | P25: 20 | Q25: =IF(P25="","",COUNTIFS($C$15:$C$2015,P$13,$D$15:$D$2015,">="&P25,$D$15:$D$2015,"<"&P26)) | S25: 30 | T25: =IF(S25="","",COUNTIFS($C$15:$C$2015,S$13,$D$15:$D$2015,">="&S25,$D$15:$D$2015,"<"&S26)) | V25: 30 | W25: =IF(V25="","",COUNTIFS($C$15:$C$2015,V$13,$D$15:$D$2015,">="&V25,$D$15:$D$2015,"<"&V26)) | Y25: 30 | Z25: =IF(Y25="","",COUNTIFS($C$15:$C$2015,Y$13,$D$15:$D$2015,">="&Y25,$D$15:$D$2015,"<"&Y26)) | AB25: 20 | AC25: =IF(AB25="","",COUNTIFS($C$15:$C$2015,AB$13,$D$15:$D$2015,">="&AB25,$D$15:$D$2015,"<"&AB26))
C26: EWS | D26: 9 | E26: 12 | G26: 21 | H26: =IF(G26="","",COUNTIFS($C$15:$C$2015,G$13,$D$15:$D$2015,">="&G26,$D$15:$D$2015,"<"&G27)) | J26: 65 | K26: =IF(J26="","",COUNTIFS($C$15:$C$2015,J$13,$D$15:$D$2015,">="&J26,$D$15:$D$2015,"<"&J27)) | M26: 32 | N26: =IF(M26="","",COUNTIFS($C$15:$C$2015,M$13,$D$15:$D$2015,">="&M26,$D$15:$D$2015,"<"&M27)) | P26: 21 | Q26: =IF(P26="","",COUNTIFS($C$15:$C$2015,P$13,$D$15:$D$2015,">="&P26,$D$15:$D$2015,"<"&P27)) | S26: 32 | T26: =IF(S26="","",COUNTIFS($C$15:$C$2015,S$13,$D$15:$D$2015,">="&S26,$D$15:$D$2015,"<"&S27)) | V26: 32 | W26: =IF(V26="","",COUNTIFS($C$15:$C$2015,V$13,$D$15:$D$2015,">="&V26,$D$15:$D$2015,"<"&V27)) | Y26: 32 | Z26: =IF(Y26="","",COUNTIFS($C$15:$C$2015,Y$13,$D$15:$D$2015,">="&Y26,$D$15:$D$2015,"<"&Y27)) | AB26: 21 | AC26: =IF(AB26="","",COUNTIFS($C$15:$C$2015,AB$13,$D$15:$D$2015,">="&AB26,$D$15:$D$2015,"<"&AB27))
C27: KAW | D27: 9 | E27: 13 | G27: 22 | H27: =IF(G27="","",COUNTIFS($C$15:$C$2015,G$13,$D$15:$D$2015,">="&G27,$D$15:$D$2015,"<"&G28)) | J27: 70 | K27: =IF(J27="","",COUNTIFS($C$15:$C$2015,J$13,$D$15:$D$2015,">="&J27,$D$15:$D$2015,"<"&J28)) | M27: 34 | N27: =IF(M27="","",COUNTIFS($C$15:$C$2015,M$13,$D$15:$D$2015,">="&M27,$D$15:$D$2015,"<"&M28)) | P27: 22 | Q27: =IF(P27="","",COUNTIFS($C$15:$C$2015,P$13,$D$15:$D$2015,">="&P27,$D$15:$D$2015,"<"&P28)) | S27: 34 | T27: =IF(S27="","",COUNTIFS($C$15:$C$2015,S$13,$D$15:$D$2015,">="&S27,$D$15:$D$2015,"<"&S28)) | V27: 34 | W27: =IF(V27="","",COUNTIFS($C$15:$C$2015,V$13,$D$15:$D$2015,">="&V27,$D$15:$D$2015,"<"&V28)) | Y27: 34 | Z27: =IF(Y27="","",COUNTIFS($C$15:$C$2015,Y$13,$D$15:$D$2015,">="&Y27,$D$15:$D$2015,"<"&Y28)) | AB27: 22 | AC27: =IF(AB27="","",COUNTIFS($C$15:$C$2015,AB$13,$D$15:$D$2015,">="&AB27,$D$15:$D$2015,"<"&AB28))
... C43: KAW | D43: 100 | E43: 29 | G43: 38 | H43: =IF(G43="","",COUNTIFS($C$15:$C$2015,G$13,$D$15:$D$2015,">="&G43,$D$15:$D$2015,"<"&G44)) | J43: 150 | K43: =IF(J43="","",COUNTIFS($C$15:$C$2015,J$13,$D$15:$D$2015,">="&J43,$D$15:$D$2015,"<"&J44)) | M43: 66 | N43: =IF(M43="","",COUNTIFS($C$15:$C$2015,M$13,$D$15:$D$2015,">="&M43,$D$15:$D$2015,"<"&M44)) | P43: 38 | Q43: =IF(P43="","",COUNTIFS($C$15:$C$2015,P$13,$D$15:$D$2015,">="&P43,$D$15:$D$2015,"<"&P44)) | S43: 66 | T43: =IF(S43="","",COUNTIFS($C$15:$C$2015,S$13,$D$15:$D$2015,">="&S43,$D$15:$D$2015,"<"&S44)) | V43: 66 | W43: =IF(V43="","",COUNTIFS($C$15:$C$2015,V$13,$D$15:$D$2015,">="&V43,$D$15:$D$2015,"<"&V44)) | Y43: 66 | Z43: =IF(Y43="","",COUNTIFS($C$15:$C$2015,Y$13,$D$15:$D$2015,">="&Y43,$D$15:$D$2015,"<"&Y44)) | AB43: 38 | AC43: =IF(AB43="","",COUNTIFS($C$15:$C$2015,AB$13,$D$15:$D$2015,">="&AB43,$D$15:$D$2015,"<"&AB44))
C44: EMU | D44: 80 | E44: 30 | G44: 39 | H44: =IF(G44="","",COUNTIFS($C$15:$C$2015,G$13,$D$15:$D$2015,">="&G44,$D$15:$D$2015,"<"&G45)) | K44: =IF(J44="","",COUNTIFS($C$15:$C$2015,J$13,$D$15:$D$2015,">="&J44,$D$15:$D$2015,"<"&J45)) | M44: 68 | N44: =IF(M44="","",COUNTIFS($C$15:$C$2015,M$13,$D$15:$D$2015,">="&M44,$D$15:$D$2015,"<"&M45)) | P44: 39 | Q44: =IF(P44="","",COUNTIFS($C$15:$C$2015,P$13,$D$15:$D$2015,">="&P44,$D$15:$D$2015,"<"&P45)) | S44: 68 | T44: =IF(S44="","",COUNTIFS($C$15:$C$2015,S$13,$D$15:$D$2015,">="&S44,$D$15:$D$2015,"<"&S45)) | V44: 68 | W44: =IF(V44="","",COUNTIFS($C$15:$C$2015,V$13,$D$15:$D$2015,">="&V44,$D$15:$D$2015,"<"&V45)) | Y44: 68 | Z44: =IF(Y44="","",COUNTIFS($C$15:$C$2015,Y$13,$D$15:$D$2015,">="&Y44,$D$15:$D$2015,"<"&Y45)) | AB44: 39 | AC44: =IF(AB44="","",COUNTIFS($C$15:$C$2015,AB$13,$D$15:$D$2015,">="&AB44,$D$15:$D$2015,"<"&AB45))
C45: EME | D45: 80 | E45: 31 | G45: 40 | H45: =IF(G45="","",COUNTIFS($C$15:$C$2015,G$13,$D$15:$D$2015,">="&G45,$D$15:$D$2015,"<"&G46)) | K45: =IF(J45="","",COUNTIFS($C$15:$C$2015,J$13,$D$15:$D$2015,">="&J45,$D$15:$D$2015,"<"&J46)) | M45: 70 | N45: =IF(M45="","",COUNTIFS($C$15:$C$2015,M$13,$D$15:$D$2015,">="&M45,$D$15:$D$2015,"<"&M46)) | P45: 40 | Q45: =IF(P45="","",COUNTIFS($C$15:$C$2015,P$13,$D$15:$D$2015,">="&P45,$D$15:$D$2015,"<"&P46)) | S45: 70 | T45: =IF(S45="","",COUNTIFS($C$15:$C$2015,S$13,$D$15:$D$2015,">="&S45,$D$15:$D$2015,"<"&S46)) | V45: 70 | W45: =IF(V45="","",COUNTIFS($C$15:$C$2015,V$13,$D$15:$D$2015,">="&V45,$D$15:$D$2015,"<"&V46)) | Y45: 70 | Z45: =IF(Y45="","",COUNTIFS($C$15:$C$2015,Y$13,$D$15:$D$2015,">="&Y45,$D$15:$D$2015,"<"&Y46)) | AB45: 40 | AC45: =IF(AB45="","",COUNTIFS($C$15:$C$2015,AB$13,$D$15:$D$2015,">="&AB45,$D$15:$D$2015,"<"&AB46))
C46: VRL | D46: 62 | E46: 32 | G46: 41 | H46: =IF(G46="","",COUNTIFS($C$15:$C$2015,G$13,$D$15:$D$2015,">="&G46,$D$15:$D$2015,"<"&G47)) | K46: =IF(J46="","",COUNTIFS($C$15:$C$2015,J$13,$D$15:$D$2015,">="&J46,$D$15:$D$2015,"<"&J47)) | M46: 72 | N46: =IF(M46="","",COUNTIFS($C$15:$C$2015,M$13,$D$15:$D$2015,">="&M46,$D$15:$D$2015,"<"&M47)) | P46: 41 | Q46: =IF(P46="","",COUNTIFS($C$15:$C$2015,P$13,$D$15:$D$2015,">="&P46,$D$15:$D$2015,"<"&P47)) | S46: 72 | T46: =IF(S46="","",COUNTIFS($C$15:$C$2015,S$13,$D$15:$D$2015,">="&S46,$D$15:$D$2015,"<"&S47)) | V46: 72 | W46: =IF(V46="","",COUNTIFS($C$15:$C$2015,V$13,$D$15:$D$2015,">="&V46,$D$15:$D$2015,"<"&V47)) | Y46: 72 | Z46: =IF(Y46="","",COUNTIFS($C$15:$C$2015,Y$13,$D$15:$D$2015,">="&Y46,$D$15:$D$2015,"<"&Y47)) | AB46: 41 | AC46: =IF(AB46="","",COUNTIFS($C$15:$C$2015,AB$13,$D$15:$D$2015,">="&AB46,$D$15:$D$2015,"<"&AB47))
C47: LTQ | D47: =+D39+1 | E47: 33 | G47: 42 | H47: =IF(G47="","",COUNTIFS($C$15:$C$2015,G$13,$D$15:$D$2015,">="&G47,$D$15:$D$2015,"<"&G48)) | K47: =IF(J47="","",COUNTIFS($C$15:$C$2015,J$13,$D$15:$D$2015,">="&J47,$D$15:$D$2015,"<"&J48)) | M47: 74 | N47: =IF(M47="","",COUNTIFS($C$15:$C$2015,M$13,$D$15:$D$2015,">="&M47,$D$15:$D$2015,"<"&M48)) | P47: 42 | Q47: =IF(P47="","",COUNTIFS($C$15:$C$2015,P$13,$D$15:$D$2015,">="&P47,$D$15:$D$2015,"<"&P48)) | S47: 74 | T47: =IF(S47="","",COUNTIFS($C$15:$C$2015,S$13,$D$15:$D$2015,">="&S47,$D$15:$D$2015,"<"&S48)) | V47: 74 | W47: =IF(V47="","",COUNTIFS($C$15:$C$2015,V$13,$D$15:$D$2015,">="&V47,$D$15:$D$2015,"<"&V48)) | Y47: 74 | Z47: =IF(Y47="","",COUNTIFS($C$15:$C$2015,Y$13,$D$15:$D$2015,">="&Y47,$D$15:$D$2015,"<"&Y48)) | AB47: 42 | AC47: =IF(AB47="","",COUNTIFS($C$15:$C$2015,AB$13,$D$15:$D$2015,">="&AB47,$D$15:$D$2015,"<"&AB48))
C48: COM | D48: =+D40+1 | E48: 34 | G48: 43 | H48: =IF(G48="","",COUNTIFS($C$15:$C$2015,G$13,$D$15:$D$2015,">="&G48,$D$15:$D$2015,"<"&G49)) | K48: =IF(J48="","",COUNTIFS($C$15:$C$2015,J$13,$D$15:$D$2015,">="&J48,$D$15:$D$2015,"<"&J49)) | M48: 76 | N48: =IF(M48="","",COUNTIFS($C$15:$C$2015,M$13,$D$15:$D$2015,">="&M48,$D$15:$D$2015,"<"&M49)) | P48: 43 | Q48: =IF(P48="","",COUNTIFS($C$15:$C$2015,P$13,$D$15:$D$2015,">="&P48,$D$15:$D$2015,"<"&P49)) | S48: 76 | T48: =IF(S48="","",COUNTIFS($C$15:$C$2015,S$13,$D$15:$D$2015,">="&S48,$D$15:$D$2015,"<"&S49)) | V48: 76 | W48: =IF(V48="","",COUNTIFS($C$15:$C$2015,V$13,$D$15:$D$2015,">="&V48,$D$15:$D$2015,"<"&V49)) | Y48: 76 | Z48: =IF(Y48="","",COUNTIFS($C$15:$C$2015,Y$13,$D$15:$D$2015,">="&Y48,$D$15:$D$2015,"<"&Y49)) | AB48: 43 | AC48: =IF(AB48="","",COUNTIFS($C$15:$C$2015,AB$13,$D$15:$D$2015,">="&AB48,$D$15:$D$2015,"<"&AB49))
C49: LJB | D49: =+D41+1 | E49: 35 | G49: 44 | H49: =IF(G49="","",COUNTIFS($C$15:$C$2015,G$13,$D$15:$D$2015,">="&G49,$D$15:$D$2015,"<"&G50)) | K49: =IF(J49="","",COUNTIFS($C$15:$C$2015,J$13,$D$15:$D$2015,">="&J49,$D$15:$D$2015,"<"&J50)) | M49: 78 | N49: =IF(M49="","",COUNTIFS($C$15:$C$2015,M$13,$D$15:$D$2015,">="&M49,$D$15:$D$2015,"<"&M50)) | P49: 44 | Q49: =IF(P49="","",COUNTIFS($C$15:$C$2015,P$13,$D$15:$D$2015,">="&P49,$D$15:$D$2015,"<"&P50)) | S49: 78 | T49: =IF(S49="","",COUNTIFS($C$15:$C$2015,S$13,$D$15:$D$2015,">="&S49,$D$15:$D$2015,"<"&S50)) | V49: 78 | W49: =IF(V49="","",COUNTIFS($C$15:$C$2015,V$13,$D$15:$D$2015,">="&V49,$D$15:$D$2015,"<"&V50)) | Y49: 78 | Z49: =IF(Y49="","",COUNTIFS($C$15:$C$2015,Y$13,$D$15:$D$2015,">="&Y49,$D$15:$D$2015,"<"&Y50)) | AB49: 44 | AC49: =IF(AB49="","",COUNTIFS($C$15:$C$2015,AB$13,$D$15:$D$2015,">="&AB49,$D$15:$D$2015,"<"&AB50))
C50: EWS | D50: =+D42+1 | E50: 36 | G50: 45 | H50: =IF(G50="","",COUNTIFS($C$15:$C$2015,G$13,$D$15:$D$2015,">="&G50,$D$15:$D$2015,"<"&G51)) | K50: =IF(J50="","",COUNTIFS($C$15:$C$2015,J$13,$D$15:$D$2015,">="&J50,$D$15:$D$2015,"<"&J51)) | M50: 80 | N50: =IF(M50="","",COUNTIFS($C$15:$C$2015,M$13,$D$15:$D$2015,">="&M50,$D$15:$D$2015,"<"&M51)) | P50: 45 | Q50: =IF(P50="","",COUNTIFS($C$15:$C$2015,P$13,$D$15:$D$2015,">="&P50,$D$15:$D$2015,"<"&P51)) | S50: 80 | T50: =IF(S50="","",COUNTIFS($C$15:$C$2015,S$13,$D$15:$D$2015,">="&S50,$D$15:$D$2015,"<"&S51)) | V50: 80 | W50: =IF(V50="","",COUNTIFS($C$15:$C$2015,V$13,$D$15:$D$2015,">="&V50,$D$15:$D$2015,"<"&V51)) | Y50: 80 | Z50: =IF(Y50="","",COUNTIFS($C$15:$C$2015,Y$13,$D$15:$D$2015,">="&Y50,$D$15:$D$2015,"<"&Y51)) | AB50: 45 | AC50: =IF(AB50="","",COUNTIFS($C$15:$C$2015,AB$13,$D$15:$D$2015,">="&AB50,$D$15:$D$2015,"<"&AB51))
C51: KAW | D51: =+D43+1 | E51: 37 | G51: 46 | H51: =IF(G51="","",COUNTIFS($C$15:$C$2015,G$13,$D$15:$D$2015,">="&G51,$D$15:$D$2015,"<"&G52)) | K51: =IF(J51="","",COUNTIFS($C$15:$C$2015,J$13,$D$15:$D$2015,">="&J51,$D$15:$D$2015,"<"&J52)) | M51: 82 | N51: =IF(M51="","",COUNTIFS($C$15:$C$2015,M$13,$D$15:$D$2015,">="&M51,$D$15:$D$2015,"<"&M52)) | P51: 46 | Q51: =IF(P51="","",COUNTIFS($C$15:$C$2015,P$13,$D$15:$D$2015,">="&P51,$D$15:$D$2015,"<"&P52)) | S51: 82 | T51: =IF(S51="","",COUNTIFS($C$15:$C$2015,S$13,$D$15:$D$2015,">="&S51,$D$15:$D$2015,"<"&S52)) | W51: =IF(V51="","",COUNTIFS($C$15:$C$2015,V$13,$D$15:$D$2015,">="&V51,$D$15:$D$2015,"<"&V52)) | Z51: =IF(Y51="","",COUNTIFS($C$15:$C$2015,Y$13,$D$15:$D$2015,">="&Y51,$D$15:$D$2015,"<"&Y52)) | AB51: 46 | AC51: =IF(AB51="","",COUNTIFS($C$15:$C$2015,AB$13,$D$15:$D$2015,">="&AB51,$D$15:$D$2015,"<"&AB52))
C52: EMU | D52: =+D44+1 | E52: 38 | G52: 47 | H52: =IF(G52="","",COUNTIFS($C$15:$C$2015,G$13,$D$15:$D$2015,">="&G52,$D$15:$D$2015,"<"&G53)) | K52: =IF(J52="","",COUNTIFS($C$15:$C$2015,J$13,$D$15:$D$2015,">="&J52,$D$15:$D$2015,"<"&J53)) | M52: 84 | N52: =IF(M52="","",COUNTIFS($C$15:$C$2015,M$13,$D$15:$D$2015,">="&M52,$D$15:$D$2015,"<"&M53)) | P52: 47 | Q52: =IF(P52="","",COUNTIFS($C$15:$C$2015,P$13,$D$15:$D$2015,">="&P52,$D$15:$D$2015,"<"&P53)) | S52: 84 | T52: =IF(S52="","",COUNTIFS($C$15:$C$2015,S$13,$D$15:$D$2015,">="&S52,$D$15:$D$2015,"<"&S53)) | W52: =IF(V52="","",COUNTIFS($C$15:$C$2015,V$13,$D$15:$D$2015,">="&V52,$D$15:$D$2015,"<"&V53)) | Z52: =IF(Y52="","",COUNTIFS($C$15:$C$2015,Y$13,$D$15:$D$2015,">="&Y52,$D$15:$D$2015,"<"&Y53)) | AB52: 47 | AC52: =IF(AB52="","",COUNTIFS($C$15:$C$2015,AB$13,$D$15:$D$2015,">="&AB52,$D$15:$D$2015,"<"&AB53))
C53: EME | D53: =+D45+1 | E53: 39 | G53: 48 | H53: =IF(G53="","",COUNTIFS($C$15:$C$2015,G$13,$D$15:$D$2015,">="&G53,$D$15:$D$2015,"<"&G54)) | K53: =IF(J53="","",COUNTIFS($C$15:$C$2015,J$13,$D$15:$D$2015,">="&J53,$D$15:$D$2015,"<"&J54)) | M53: 86 | N53: =IF(M53="","",COUNTIFS($C$15:$C$2015,M$13,$D$15:$D$2015,">="&M53,$D$15:$D$2015,"<"&M54)) | P53: 48 | Q53: =IF(P53="","",COUNTIFS($C$15:$C$2015,P$13,$D$15:$D$2015,">="&P53,$D$15:$D$2015,"<"&P54)) | S53: 86 | T53: =IF(S53="","",COUNTIFS($C$15:$C$2015,S$13,$D$15:$D$2015,">="&S53,$D$15:$D$2015,"<"&S54)) | W53: =IF(V53="","",COUNTIFS($C$15:$C$2015,V$13,$D$15:$D$2015,">="&V53,$D$15:$D$2015,"<"&V54)) | Z53: =IF(Y53="","",COUNTIFS($C$15:$C$2015,Y$13,$D$15:$D$2015,">="&Y53,$D$15:$D$2015,"<"&Y54)) | AB53: 48 | AC53: =IF(AB53="","",COUNTIFS($C$15:$C$2015,AB$13,$D$15:$D$2015,">="&AB53,$D$15:$D$2015,"<"&AB54))
C54: VRL | D54: =+D46+1 | E54: 40 | G54: 49 | H54: =IF(G54="","",COUNTIFS($C$15:$C$2015,G$13,$D$15:$D$2015,">="&G54,$D$15:$D$2015,"<"&G55)) | K54: =IF(J54="","",COUNTIFS($C$15:$C$2015,J$13,$D$15:$D$2015,">="&J54,$D$15:$D$2015,"<"&J55)) | M54: 88 | N54: =IF(M54="","",COUNTIFS($C$15:$C$2015,M$13,$D$15:$D$2015,">="&M54,$D$15:$D$2015,"<"&M55)) | P54: 49 | Q54: =IF(P54="","",COUNTIFS($C$15:$C$2015,P$13,$D$15:$D$2015,">="&P54,$D$15:$D$2015,"<"&P55)) | S54: 88 | T54: =IF(S54="","",COUNTIFS($C$15:$C$2015,S$13,$D$15:$D$2015,">="&S54,$D$15:$D$2015,"<"&S55)) | W54: =IF(V54="","",COUNTIFS($C$15:$C$2015,V$13,$D$15:$D$2015,">="&V54,$D$15:$D$2015,"<"&V55)) | Z54: =IF(Y54="","",COUNTIFS($C$15:$C$2015,Y$13,$D$15:$D$2015,">="&Y54,$D$15:$D$2015,"<"&Y55)) | AB54: 49 | AC54: =IF(AB54="","",COUNTIFS($C$15:$C$2015,AB$13,$D$15:$D$2015,">="&AB54,$D$15:$D$2015,"<"&AB55))
C55: LTQ | D55: =+D39+10 | E55: 41 | G55: 50 | H55: =IF(G55="","",COUNTIFS($C$15:$C$2015,G$13,$D$15:$D$2015,">="&G55,$D$15:$D$2015,"<"&G56)) | K55: =IF(J55="","",COUNTIFS($C$15:$C$2015,J$13,$D$15:$D$2015,">="&J55,$D$15:$D$2015,"<"&J56)) | M55: 90 | N55: =IF(M55="","",COUNTIFS($C$15:$C$2015,M$13,$D$15:$D$2015,">="&M55,$D$15:$D$2015,"<"&M56)) | P55: 50 | Q55: =IF(P55="","",COUNTIFS($C$15:$C$2015,P$13,$D$15:$D$2015,">="&P55,$D$15:$D$2015,"<"&P56)) | S55: 90 | T55: =IF(S55="","",COUNTIFS($C$15:$C$2015,S$13,$D$15:$D$2015,">="&S55,$D$15:$D$2015,"<"&S56)) | W55: =IF(V55="","",COUNTIFS($C$15:$C$2015,V$13,$D$15:$D$2015,">="&V55,$D$15:$D$2015,"<"&V56)) | Z55: =IF(Y55="","",COUNTIFS($C$15:$C$2015,Y$13,$D$15:$D$2015,">="&Y55,$D$15:$D$2015,"<"&Y56)) | AB55: 50 | AC55: =IF(AB55="","",COUNTIFS($C$15:$C$2015,AB$13,$D$15:$D$2015,">="&AB55,$D$15:$D$2015,"<"&AB56))
...

Sheet M-02
G1: =FAO!B1&" max =" | H1: =+FAO!B10 | J1: =FAO!E1&" max =" | K1: =+FAO!E10 | M1: =FAO!H1&" max =" | N1: =+FAO!H10 | P1: =FAO!K1&" max =" | Q1: =+FAO!K10 | S1: =FAO!N1&" max =" | T1: =+FAO!N10 | V1: =FAO!Q1&" max =" | W1: =+FAO!Q10 | Y1: =FAO!T1&" max =" | Z1: =+FAO!T10 | AB1: =FAO!W1&" max =" | AC1: =+FAO!W10
G2: obs n = | H2: =COUNTIF($C$18:$C$1003,G13) | J2: obs n = | K2: =COUNTIF($C$18:$C$1003,J13) | M2: obs n = | N2: =COUNTIF($C$18:$C$1003,M13) | P2: obs n = | Q2: =COUNTIF($C$18:$C$1003,P13) | S2: obs n = | T2: =COUNTIF($C$18:$C$1003,S13) | V2: obs n = | W2: =COUNTIF($C$18:$C$1003,V13) | Y2: obs n = | Z2: =COUNTIF($C$18:$C$1003,Y13) | AB2: obs n = | AC2: =COUNTIF($C$18:$C$1003,AB13)
G3: freq n= | H3: =+SUM(H15:H1003) | J3: freq n= | K3: =+SUM(K15:K1003) | M3: freq n= | N3: =+SUM(N15:N1003) | P3: freq n= | Q3: =+SUM(Q15:Q1003) | S3: freq n= | T3: =+SUM(T15:T1003) | V3: freq n= | W3: =+SUM(W15:W1003) | Y3: freq n= | Z3: =+SUM(Z15:Z1003) | AB3: freq n= | AC3: =+SUM(AC15:AC1003)
G4: first bin = | H4: 10 | J4: first bin = | K4: 10 | M4: first bin = | N4: 10 | P4: first bin = | Q4: 10 | S4: first bin = | T4: 10 | V4: first bin = | W4: 10 | Y4: first bin = | Z4: 10 | AB4: first bin = | AC4: 10
G5: increment = | H5: =+FAO!B14 | J5: increment = | K5: =+FAO!E14 | M5: increment = | N5: =+FAO!H14 | P5: increment = | Q5: =+FAO!K14 | S5: increment = | T5: =+FAO!N14 | V5: increment = | W5: =+FAO!Q14 | Y5: increment = | Z5: =+FAO!T14 | AB5: increment = | AC5: =+FAO!W14
G6: Complete = | H6: =COUNTIFS($C$18:$C$2015,G$13,$D$18:$D$2015,">5")/COUNTIF($C$18:$C$2015,G$13)*100 | J6: Complete = | K6: =COUNTIFS($C$18:$C$2015,J$13,$D$18:$D$2015,">5")/COUNTIF($C$18:$C$2015,J$13)*100 | M6: Complete = | N6: =COUNTIFS($C$18:$C$2015,M$13,$D$18:$D$2015,">5")/COUNTIF($C$18:$C$2015,M$13)*100 | P6: Complete = | Q6: =COUNTIFS($C$18:$C$2015,P$13,$D$18:$D$2015,">5")/COUNTIF($C$18:$C$2015,P$13)*100 | S6: Complete = | T6: =COUNTIFS($C$18:$C$2015,S$13,$D$18:$D$2015,">5")/COUNTIF($C$18:$C$2015,S$13)*100 | V6: Complete = | W6: =COUNTIFS($C$18:$C$2015,V$13,$D$18:$D$2015,">5")/COUNTIF($C$18:$C$2015,V$13)*100 | Y6: Complete = | Z6: =COUNTIFS($C$18:$C$2015,Y$13,$D$18:$D$2015,">5")/COUNTIF($C$18:$C$2015,Y$13)*100 | AB6: Complete = | AC6: =COUNTIFS($C$18:$C$2015,AB$13,$D$18:$D$2015,">5")/COUNTIF($C$18:$C$2015,AB$13)*100
G7: L50 (cm) = | H7: =+FAO!B11 | J7: L50 (cm) = | K7: =+FAO!E11 | M7: L50 (cm) = | N7: =+FAO!H11 | P7: L50 (cm) = | Q7: =+FAO!K11 | S7: L50 (cm) = | T7: =+FAO!N11 | V7: L50 (cm) = | W7: =+FAO!Q11 | Y7: L50 (cm) = | Z7: =+FAO!T11 | AB7: L50 (cm) = | AC7: =+FAO!W11
G8: Juven. (%) = | H8: =+ROUND(COUNTIFS($C$18:$C$2015,G$13,$D$18:$D$2015,"<"&H7)/COUNTIF($C$18:$C$2015,G$13)*100,0) | J8: Juven. (%) = | K8: =+ROUND(COUNTIFS($C$18:$C$2015,J$13,$D$18:$D$2015,"<"&K7)/COUNTIF($C$18:$C$2015,J$13)*100,0) | M8: Juven. (%) = | N8: =+ROUND(COUNTIFS($C$18:$C$2015,M$13,$D$18:$D$2015,"<"&N7)/COUNTIF($C$18:$C$2015,M$13)*100,0) | P8: Juven. (%) = | Q8: =+ROUND(COUNTIFS($C$18:$C$2015,P$13,$D$18:$D$2015,"<"&Q7)/COUNTIF($C$18:$C$2015,P$13)*100,0) | S8: Juven. (%) = | T8: =+ROUND(COUNTIFS($C$18:$C$2015,S$13,$D$18:$D$2015,"<"&T7)/COUNTIF($C$18:$C$2015,S$13)*100,0) | V8: Juven. (%) = | W8: =+ROUND(COUNTIFS($C$18:$C$2015,V$13,$D$18:$D$2015,"<"&W7)/COUNTIF($C$18:$C$2015,V$13)*100,0) | Y8: Juven. (%) = | Z8: =+ROUND(COUNTIFS($C$18:$C$2015,Y$13,$D$18:$D$2015,"<"&Z7)/COUNTIF($C$18:$C$2015,Y$13)*100,0) | AB8: Juven. (%) = | AC8: =+ROUND(COUNTIFS($C$18:$C$2015,AB$13,$D$18:$D$2015,"<"&AC7)/COUNTIF($C$18:$C$2015,AB$13)*100,0)
G9: =+FAO!B6 | J9: =+FAO!E6 | M9: =+FAO!H6 | P9: =+FAO!K6 | S9: =+FAO!N6 | V9: =+FAO!Q6 | Y9: =+FAO!T6 | AB9: =+FAO!W6
G10: =+FAO!B7 | J10: =+FAO!E7 | M10: =+FAO!H7 | P10: =+FAO!K7 | S10: =+FAO!N7 | V10: =+FAO!Q7 | Y10: =+FAO!T7 | AB10: =+FAO!W7
G11: =+FAO!B9 | J11: =+FAO!E9 | M11: =+FAO!H9 | P11: =+FAO!K9 | S11: =+FAO!N9 | V11: =+FAO!Q9 | Y11: =+FAO!T9 | AB11: =+FAO!W9
G12: =+FAO!B5 | J12: =+FAO!E5 | M12: =+FAO!H5 | P12: =+FAO!K5 | S12: =+FAO!N5 | V12: =+FAO!Q5 | Y12: =+FAO!T5 | AB12: =+FAO!W5
D13: #VALUE! | E13: =COUNTA(C15:C1003) | G13: =+FAO!B1 | H13: =+FAO!B3 | J13: =+FAO!E1 | K13: =+FAO!E3 | M13: =+FAO!H1 | N13: =+FAO!H3 | P13: =+FAO!K1 | Q13: =+FAO!K3 | S13: =+FAO!N1 | T13: =+FAO!N3 | V13: =+FAO!Q1 | W13: =+FAO!Q3 | Y13: =+FAO!T1 | Z13: =+FAO!T3 | AB13: =+FAO!W1 | AC13: =+FAO!W3
A14: TRIP | B14: DATE | C14: FAO | D14: OBS | E14: ID | G14: ="LC-"&G13 | H14: ="FQ-"&G13 | J14: ="LC-"&J13 | K14: ="FQ-"&J13 | M14: ="LC-"&M13 | N14: ="FQ-"&M13 | P14: ="LC-"&P13 | Q14: ="FQ-"&P13 | S14: ="LC-"&S13 | T14: ="FQ-"&S13 | V14: ="LC-"&V13 | W14: ="FQ-"&V13 | Y14: ="LC-"&Y13 | Z14: ="FQ-"&Y13 | AB14: ="LC-"&AB13 | AC14: ="FQ-"&AB13
E15: {=+_xlfn.SEQUENCE(E13,1,1)} | G15: {=_xlfn.SEQUENCE(((H1-H4)/H5)+1, 1, H4, H5)} | H15: =IF(G15="","",COUNTIFS($C$18:$C$2015,G$13,$D$18:$D$2015,">="&G15,$D$18:$D$2015,"<"&G16)) | J15: {=_xlfn.SEQUENCE(((K1-K4)/K5)+1, 1, K4, K5)} | K15: =IF(J15="","",COUNTIFS($C$18:$C$2015,J$13,$D$18:$D$2015,">="&J15,$D$18:$D$2015,"<"&J16)) | M15: {=_xlfn.SEQUENCE(((N1-N4)/N5)+1, 1, N4, N5)} | N15: =IF(M15="","",COUNTIFS($C$18:$C$2015,M$13,$D$18:$D$2015,">="&M15,$D$18:$D$2015,"<"&M16)) | P15: {=_xlfn.SEQUENCE(((Q1-Q4)/Q5)+1, 1, Q4, Q5)} | Q15: =IF(P15="","",COUNTIFS($C$18:$C$2015,P$13,$D$18:$D$2015,">="&P15,$D$18:$D$2015,"<"&P16)) | S15: {=_xlfn.SEQUENCE(((T1-T4)/T5)+1, 1, T4, T5)} | T15: =IF(S15="","",COUNTIFS($C$18:$C$2015,S$13,$D$18:$D$2015,">="&S15,$D$18:$D$2015,"<"&S16)) | V15: {=_xlfn.SEQUENCE(((W1-W4)/W5)+1, 1, W4, W5)} | W15: =IF(V15="","",COUNTIFS($C$18:$C$2015,V$13,$D$18:$D$2015,">="&V15,$D$18:$D$2015,"<"&V16)) | Y15: {=_xlfn.SEQUENCE(((Z1-Z4)/Z5)+1, 1, Z4, Z5)} | Z15: =IF(Y15="","",COUNTIFS($C$18:$C$2015,Y$13,$D$18:$D$2015,">="&Y15,$D$18:$D$2015,"<"&Y16)) | AB15: {=_xlfn.SEQUENCE(((AC1-AC4)/AC5)+1, 1, AC4, AC5)} | AC15: =IF(AB15="","",COUNTIFS($C$18:$C$2015,AB$13,$D$18:$D$2015,">="&AB15,$D$18:$D$2015,"<"&AB16))
G16: 11 | H16: =IF(G16="","",COUNTIFS($C$18:$C$2015,G$13,$D$18:$D$2015,">="&G16,$D$18:$D$2015,"<"&G17)) | J16: 15 | K16: =IF(J16="","",COUNTIFS($C$18:$C$2015,J$13,$D$18:$D$2015,">="&J16,$D$18:$D$2015,"<"&J17)) | M16: 12 | N16: =IF(M16="","",COUNTIFS($C$18:$C$2015,M$13,$D$18:$D$2015,">="&M16,$D$18:$D$2015,"<"&M17)) | P16: 11 | Q16: =IF(P16="","",COUNTIFS($C$18:$C$2015,P$13,$D$18:$D$2015,">="&P16,$D$18:$D$2015,"<"&P17)) | S16: 12 | T16: =IF(S16="","",COUNTIFS($C$18:$C$2015,S$13,$D$18:$D$2015,">="&S16,$D$18:$D$2015,"<"&S17)) | V16: 12 | W16: =IF(V16="","",COUNTIFS($C$18:$C$2015,V$13,$D$18:$D$2015,">="&V16,$D$18:$D$2015,"<"&V17)) | Y16: 12 | Z16: =IF(Y16="","",COUNTIFS($C$18:$C$2015,Y$13,$D$18:$D$2015,">="&Y16,$D$18:$D$2015,"<"&Y17)) | AB16: 11 | AC16: =IF(AB16="","",COUNTIFS($C$18:$C$2015,AB$13,$D$18:$D$2015,">="&AB16,$D$18:$D$2015,"<"&AB17))
G17: 12 | H17: =IF(G17="","",COUNTIFS($C$18:$C$2015,G$13,$D$18:$D$2015,">="&G17,$D$18:$D$2015,"<"&G18)) | J17: 20 | K17: =IF(J17="","",COUNTIFS($C$18:$C$2015,J$13,$D$18:$D$2015,">="&J17,$D$18:$D$2015,"<"&J18)) | M17: 14 | N17: =IF(M17="","",COUNTIFS($C$18:$C$2015,M$13,$D$18:$D$2015,">="&M17,$D$18:$D$2015,"<"&M18)) | P17: 12 | Q17: =IF(P17="","",COUNTIFS($C$18:$C$2015,P$13,$D$18:$D$2015,">="&P17,$D$18:$D$2015,"<"&P18)) | S17: 14 | T17: =IF(S17="","",COUNTIFS($C$18:$C$2015,S$13,$D$18:$D$2015,">="&S17,$D$18:$D$2015,"<"&S18)) | V17: 14 | W17: =IF(V17="","",COUNTIFS($C$18:$C$2015,V$13,$D$18:$D$2015,">="&V17,$D$18:$D$2015,"<"&V18)) | Y17: 14 | Z17: =IF(Y17="","",COUNTIFS($C$18:$C$2015,Y$13,$D$18:$D$2015,">="&Y17,$D$18:$D$2015,"<"&Y18)) | AB17: 12 | AC17: =IF(AB17="","",COUNTIFS($C$18:$C$2015,AB$13,$D$18:$D$2015,">="&AB17,$D$18:$D$2015,"<"&AB18))
G18: 13 | H18: =IF(G18="","",COUNTIFS($C$18:$C$2015,G$13,$D$18:$D$2015,">="&G18,$D$18:$D$2015,"<"&G19)) | J18: 25 | K18: =IF(J18="","",COUNTIFS($C$18:$C$2015,J$13,$D$18:$D$2015,">="&J18,$D$18:$D$2015,"<"&J19)) | M18: 16 | N18: =IF(M18="","",COUNTIFS($C$18:$C$2015,M$13,$D$18:$D$2015,">="&M18,$D$18:$D$2015,"<"&M19)) | P18: 13 | Q18: =IF(P18="","",COUNTIFS($C$18:$C$2015,P$13,$D$18:$D$2015,">="&P18,$D$18:$D$2015,"<"&P19)) | S18: 16 | T18: =IF(S18="","",COUNTIFS($C$18:$C$2015,S$13,$D$18:$D$2015,">="&S18,$D$18:$D$2015,"<"&S19)) | V18: 16 | W18: =IF(V18="","",COUNTIFS($C$18:$C$2015,V$13,$D$18:$D$2015,">="&V18,$D$18:$D$2015,"<"&V19)) | Y18: 16 | Z18: =IF(Y18="","",COUNTIFS($C$18:$C$2015,Y$13,$D$18:$D$2015,">="&Y18,$D$18:$D$2015,"<"&Y19)) | AB18: 13 | AC18: =IF(AB18="","",COUNTIFS($C$18:$C$2015,AB$13,$D$18:$D$2015,">="&AB18,$D$18:$D$2015,"<"&AB19))
G19: 14 | H19: =IF(G19="","",COUNTIFS($C$18:$C$2015,G$13,$D$18:$D$2015,">="&G19,$D$18:$D$2015,"<"&G20)) | J19: 30 | K19: =IF(J19="","",COUNTIFS($C$18:$C$2015,J$13,$D$18:$D$2015,">="&J19,$D$18:$D$2015,"<"&J20)) | M19: 18 | N19: =IF(M19="","",COUNTIFS($C$18:$C$2015,M$13,$D$18:$D$2015,">="&M19,$D$18:$D$2015,"<"&M20)) | P19: 14 | Q19: =IF(P19="","",COUNTIFS($C$18:$C$2015,P$13,$D$18:$D$2015,">="&P19,$D$18:$D$2015,"<"&P20)) | S19: 18 | T19: =IF(S19="","",COUNTIFS($C$18:$C$2015,S$13,$D$18:$D$2015,">="&S19,$D$18:$D$2015,"<"&S20)) | V19: 18 | W19: =IF(V19="","",COUNTIFS($C$18:$C$2015,V$13,$D$18:$D$2015,">="&V19,$D$18:$D$2015,"<"&V20)) | Y19: 18 | Z19: =IF(Y19="","",COUNTIFS($C$18:$C$2015,Y$13,$D$18:$D$2015,">="&Y19,$D$18:$D$2015,"<"&Y20)) | AB19: 14 | AC19: =IF(AB19="","",COUNTIFS($C$18:$C$2015,AB$13,$D$18:$D$2015,">="&AB19,$D$18:$D$2015,"<"&AB20))
G20: 15 | H20: =IF(G20="","",COUNTIFS($C$18:$C$2015,G$13,$D$18:$D$2015,">="&G20,$D$18:$D$2015,"<"&G21)) | J20: 35 | K20: =IF(J20="","",COUNTIFS($C$18:$C$2015,J$13,$D$18:$D$2015,">="&J20,$D$18:$D$2015,"<"&J21)) | M20: 20 | N20: =IF(M20="","",COUNTIFS($C$18:$C$2015,M$13,$D$18:$D$2015,">="&M20,$D$18:$D$2015,"<"&M21)) | P20: 15 | Q20: =IF(P20="","",COUNTIFS($C$18:$C$2015,P$13,$D$18:$D$2015,">="&P20,$D$18:$D$2015,"<"&P21)) | S20: 20 | T20: =IF(S20="","",COUNTIFS($C$18:$C$2015,S$13,$D$18:$D$2015,">="&S20,$D$18:$D$2015,"<"&S21)) | V20: 20 | W20: =IF(V20="","",COUNTIFS($C$18:$C$2015,V$13,$D$18:$D$2015,">="&V20,$D$18:$D$2015,"<"&V21)) | Y20: 20 | Z20: =IF(Y20="","",COUNTIFS($C$18:$C$2015,Y$13,$D$18:$D$2015,">="&Y20,$D$18:$D$2015,"<"&Y21)) | AB20: 15 | AC20: =IF(AB20="","",COUNTIFS($C$18:$C$2015,AB$13,$D$18:$D$2015,">="&AB20,$D$18:$D$2015,"<"&AB21))
G21: 16 | H21: =IF(G21="","",COUNTIFS($C$18:$C$2015,G$13,$D$18:$D$2015,">="&G21,$D$18:$D$2015,"<"&G22)) | J21: 40 | K21: =IF(J21="","",COUNTIFS($C$18:$C$2015,J$13,$D$18:$D$2015,">="&J21,$D$18:$D$2015,"<"&J22)) | M21: 22 | N21: =IF(M21="","",COUNTIFS($C$18:$C$2015,M$13,$D$18:$D$2015,">="&M21,$D$18:$D$2015,"<"&M22)) | P21: 16 | Q21: =IF(P21="","",COUNTIFS($C$18:$C$2015,P$13,$D$18:$D$2015,">="&P21,$D$18:$D$2015,"<"&P22)) | S21: 22 | T21: =IF(S21="","",COUNTIFS($C$18:$C$2015,S$13,$D$18:$D$2015,">="&S21,$D$18:$D$2015,"<"&S22)) | V21: 22 | W21: =IF(V21="","",COUNTIFS($C$18:$C$2015,V$13,$D$18:$D$2015,">="&V21,$D$18:$D$2015,"<"&V22)) | Y21: 22 | Z21: =IF(Y21="","",COUNTIFS($C$18:$C$2015,Y$13,$D$18:$D$2015,">="&Y21,$D$18:$D$2015,"<"&Y22)) | AB21: 16 | AC21: =IF(AB21="","",COUNTIFS($C$18:$C$2015,AB$13,$D$18:$D$2015,">="&AB21,$D$18:$D$2015,"<"&AB22))
G22: 17 | H22: =IF(G22="","",COUNTIFS($C$18:$C$2015,G$13,$D$18:$D$2015,">="&G22,$D$18:$D$2015,"<"&G23)) | J22: 45 | K22: =IF(J22="","",COUNTIFS($C$18:$C$2015,J$13,$D$18:$D$2015,">="&J22,$D$18:$D$2015,"<"&J23)) | M22: 24 | N22: =IF(M22="","",COUNTIFS($C$18:$C$2015,M$13,$D$18:$D$2015,">="&M22,$D$18:$D$2015,"<"&M23)) | P22: 17 | Q22: =IF(P22="","",COUNTIFS($C$18:$C$2015,P$13,$D$18:$D$2015,">="&P22,$D$18:$D$2015,"<"&P23)) | S22: 24 | T22: =IF(S22="","",COUNTIFS($C$18:$C$2015,S$13,$D$18:$D$2015,">="&S22,$D$18:$D$2015,"<"&S23)) | V22: 24 | W22: =IF(V22="","",COUNTIFS($C$18:$C$2015,V$13,$D$18:$D$2015,">="&V22,$D$18:$D$2015,"<"&V23)) | Y22: 24 | Z22: =IF(Y22="","",COUNTIFS($C$18:$C$2015,Y$13,$D$18:$D$2015,">="&Y22,$D$18:$D$2015,"<"&Y23)) | AB22: 17 | AC22: =IF(AB22="","",COUNTIFS($C$18:$C$2015,AB$13,$D$18:$D$2015,">="&AB22,$D$18:$D$2015,"<"&AB23))
G23: 18 | H23: =IF(G23="","",COUNTIFS($C$18:$C$2015,G$13,$D$18:$D$2015,">="&G23,$D$18:$D$2015,"<"&G24)) | J23: 50 | K23: =IF(J23="","",COUNTIFS($C$18:$C$2015,J$13,$D$18:$D$2015,">="&J23,$D$18:$D$2015,"<"&J24)) | M23: 26 | N23: =IF(M23="","",COUNTIFS($C$18:$C$2015,M$13,$D$18:$D$2015,">="&M23,$D$18:$D$2015,"<"&M24)) | P23: 18 | Q23: =IF(P23="","",COUNTIFS($C$18:$C$2015,P$13,$D$18:$D$2015,">="&P23,$D$18:$D$2015,"<"&P24)) | S23: 26 | T23: =IF(S23="","",COUNTIFS($C$18:$C$2015,S$13,$D$18:$D$2015,">="&S23,$D$18:$D$2015,"<"&S24)) | V23: 26 | W23: =IF(V23="","",COUNTIFS($C$18:$C$2015,V$13,$D$18:$D$2015,">="&V23,$D$18:$D$2015,"<"&V24)) | Y23: 26 | Z23: =IF(Y23="","",COUNTIFS($C$18:$C$2015,Y$13,$D$18:$D$2015,">="&Y23,$D$18:$D$2015,"<"&Y24)) | AB23: 18 | AC23: =IF(AB23="","",COUNTIFS($C$18:$C$2015,AB$13,$D$18:$D$2015,">="&AB23,$D$18:$D$2015,"<"&AB24))
G24: 19 | H24: =IF(G24="","",COUNTIFS($C$18:$C$2015,G$13,$D$18:$D$2015,">="&G24,$D$18:$D$2015,"<"&G25)) | J24: 55 | K24: =IF(J24="","",COUNTIFS($C$18:$C$2015,J$13,$D$18:$D$2015,">="&J24,$D$18:$D$2015,"<"&J25)) | M24: 28 | N24: =IF(M24="","",COUNTIFS($C$18:$C$2015,M$13,$D$18:$D$2015,">="&M24,$D$18:$D$2015,"<"&M25)) | P24: 19 | Q24: =IF(P24="","",COUNTIFS($C$18:$C$2015,P$13,$D$18:$D$2015,">="&P24,$D$18:$D$2015,"<"&P25)) | S24: 28 | T24: =IF(S24="","",COUNTIFS($C$18:$C$2015,S$13,$D$18:$D$2015,">="&S24,$D$18:$D$2015,"<"&S25)) | V24: 28 | W24: =IF(V24="","",COUNTIFS($C$18:$C$2015,V$13,$D$18:$D$2015,">="&V24,$D$18:$D$2015,"<"&V25)) | Y24: 28 | Z24: =IF(Y24="","",COUNTIFS($C$18:$C$2015,Y$13,$D$18:$D$2015,">="&Y24,$D$18:$D$2015,"<"&Y25)) | AB24: 19 | AC24: =IF(AB24="","",COUNTIFS($C$18:$C$2015,AB$13,$D$18:$D$2015,">="&AB24,$D$18:$D$2015,"<"&AB25))
G25: 20 | H25: =IF(G25="","",COUNTIFS($C$18:$C$2015,G$13,$D$18:$D$2015,">="&G25,$D$18:$D$2015,"<"&G26)) | J25: 60 | K25: =IF(J25="","",COUNTIFS($C$18:$C$2015,J$13,$D$18:$D$2015,">="&J25,$D$18:$D$2015,"<"&J26)) | M25: 30 | N25: =IF(M25="","",COUNTIFS($C$18:$C$2015,M$13,$D$18:$D$2015,">="&M25,$D$18:$D$2015,"<"&M26)) | P25: 20 | Q25: =IF(P25="","",COUNTIFS($C$18:$C$2015,P$13,$D$18:$D$2015,">="&P25,$D$18:$D$2015,"<"&P26)) | S25: 30 | T25: =IF(S25="","",COUNTIFS($C$18:$C$2015,S$13,$D$18:$D$2015,">="&S25,$D$18:$D$2015,"<"&S26)) | V25: 30 | W25: =IF(V25="","",COUNTIFS($C$18:$C$2015,V$13,$D$18:$D$2015,">="&V25,$D$18:$D$2015,"<"&V26)) | Y25: 30 | Z25: =IF(Y25="","",COUNTIFS($C$18:$C$2015,Y$13,$D$18:$D$2015,">="&Y25,$D$18:$D$2015,"<"&Y26)) | AB25: 20 | AC25: =IF(AB25="","",COUNTIFS($C$18:$C$2015,AB$13,$D$18:$D$2015,">="&AB25,$D$18:$D$2015,"<"&AB26))
G26: 21 | H26: =IF(G26="","",COUNTIFS($C$18:$C$2015,G$13,$D$18:$D$2015,">="&G26,$D$18:$D$2015,"<"&G27)) | J26: 65 | K26: =IF(J26="","",COUNTIFS($C$18:$C$2015,J$13,$D$18:$D$2015,">="&J26,$D$18:$D$2015,"<"&J27)) | M26: 32 | N26: =IF(M26="","",COUNTIFS($C$18:$C$2015,M$13,$D$18:$D$2015,">="&M26,$D$18:$D$2015,"<"&M27)) | P26: 21 | Q26: =IF(P26="","",COUNTIFS($C$18:$C$2015,P$13,$D$18:$D$2015,">="&P26,$D$18:$D$2015,"<"&P27)) | S26: 32 | T26: =IF(S26="","",COUNTIFS($C$18:$C$2015,S$13,$D$18:$D$2015,">="&S26,$D$18:$D$2015,"<"&S27)) | V26: 32 | W26: =IF(V26="","",COUNTIFS($C$18:$C$2015,V$13,$D$18:$D$2015,">="&V26,$D$18:$D$2015,"<"&V27)) | Y26: 32 | Z26: =IF(Y26="","",COUNTIFS($C$18:$C$2015,Y$13,$D$18:$D$2015,">="&Y26,$D$18:$D$2015,"<"&Y27)) | AB26: 21 | AC26: =IF(AB26="","",COUNTIFS($C$18:$C$2015,AB$13,$D$18:$D$2015,">="&AB26,$D$18:$D$2015,"<"&AB27))
G27: 22 | H27: =IF(G27="","",COUNTIFS($C$18:$C$2015,G$13,$D$18:$D$2015,">="&G27,$D$18:$D$2015,"<"&G28)) | J27: 70 | K27: =IF(J27="","",COUNTIFS($C$18:$C$2015,J$13,$D$18:$D$2015,">="&J27,$D$18:$D$2015,"<"&J28)) | M27: 34 | N27: =IF(M27="","",COUNTIFS($C$18:$C$2015,M$13,$D$18:$D$2015,">="&M27,$D$18:$D$2015,"<"&M28)) | P27: 22 | Q27: =IF(P27="","",COUNTIFS($C$18:$C$2015,P$13,$D$18:$D$2015,">="&P27,$D$18:$D$2015,"<"&P28)) | S27: 34 | T27: =IF(S27="","",COUNTIFS($C$18:$C$2015,S$13,$D$18:$D$2015,">="&S27,$D$18:$D$2015,"<"&S28)) | V27: 34 | W27: =IF(V27="","",COUNTIFS($C$18:$C$2015,V$13,$D$18:$D$2015,">="&V27,$D$18:$D$2015,"<"&V28)) | Y27: 34 | Z27: =IF(Y27="","",COUNTIFS($C$18:$C$2015,Y$13,$D$18:$D$2015,">="&Y27,$D$18:$D$2015,"<"&Y28)) | AB27: 22 | AC27: =IF(AB27="","",COUNTIFS($C$18:$C$2015,AB$13,$D$18:$D$2015,">="&AB27,$D$18:$D$2015,"<"&AB28))
... G43: 38 | H43: =IF(G43="","",COUNTIFS($C$18:$C$2015,G$13,$D$18:$D$2015,">="&G43,$D$18:$D$2015,"<"&G44)) | J43: 150 | K43: =IF(J43="","",COUNTIFS($C$18:$C$2015,J$13,$D$18:$D$2015,">="&J43,$D$18:$D$2015,"<"&J44)) | M43: 66 | N43: =IF(M43="","",COUNTIFS($C$18:$C$2015,M$13,$D$18:$D$2015,">="&M43,$D$18:$D$2015,"<"&M44)) | P43: 38 | Q43: =IF(P43="","",COUNTIFS($C$18:$C$2015,P$13,$D$18:$D$2015,">="&P43,$D$18:$D$2015,"<"&P44)) | S43: 66 | T43: =IF(S43="","",COUNTIFS($C$18:$C$2015,S$13,$D$18:$D$2015,">="&S43,$D$18:$D$2015,"<"&S44)) | V43: 66 | W43: =IF(V43="","",COUNTIFS($C$18:$C$2015,V$13,$D$18:$D$2015,">="&V43,$D$18:$D$2015,"<"&V44)) | Y43: 66 | Z43: =IF(Y43="","",COUNTIFS($C$18:$C$2015,Y$13,$D$18:$D$2015,">="&Y43,$D$18:$D$2015,"<"&Y44)) | AB43: 38 | AC43: =IF(AB43="","",COUNTIFS($C$18:$C$2015,AB$13,$D$18:$D$2015,">="&AB43,$D$18:$D$2015,"<"&AB44))
G44: 39 | H44: =IF(G44="","",COUNTIFS($C$18:$C$2015,G$13,$D$18:$D$2015,">="&G44,$D$18:$D$2015,"<"&G45)) | K44: =IF(J44="","",COUNTIFS($C$18:$C$2015,J$13,$D$18:$D$2015,">="&J44,$D$18:$D$2015,"<"&J45)) | M44: 68 | N44: =IF(M44="","",COUNTIFS($C$18:$C$2015,M$13,$D$18:$D$2015,">="&M44,$D$18:$D$2015,"<"&M45)) | P44: 39 | Q44: =IF(P44="","",COUNTIFS($C$18:$C$2015,P$13,$D$18:$D$2015,">="&P44,$D$18:$D$2015,"<"&P45)) | S44: 68 | T44: =IF(S44="","",COUNTIFS($C$18:$C$2015,S$13,$D$18:$D$2015,">="&S44,$D$18:$D$2015,"<"&S45)) | V44: 68 | W44: =IF(V44="","",COUNTIFS($C$18:$C$2015,V$13,$D$18:$D$2015,">="&V44,$D$18:$D$2015,"<"&V45)) | Y44: 68 | Z44: =IF(Y44="","",COUNTIFS($C$18:$C$2015,Y$13,$D$18:$D$2015,">="&Y44,$D$18:$D$2015,"<"&Y45)) | AB44: 39 | AC44: =IF(AB44="","",COUNTIFS($C$18:$C$2015,AB$13,$D$18:$D$2015,">="&AB44,$D$18:$D$2015,"<"&AB45))
G45: 40 | H45: =IF(G45="","",COUNTIFS($C$18:$C$2015,G$13,$D$18:$D$2015,">="&G45,$D$18:$D$2015,"<"&G46)) | K45: =IF(J45="","",COUNTIFS($C$18:$C$2015,J$13,$D$18:$D$2015,">="&J45,$D$18:$D$2015,"<"&J46)) | M45: 70 | N45: =IF(M45="","",COUNTIFS($C$18:$C$2015,M$13,$D$18:$D$2015,">="&M45,$D$18:$D$2015,"<"&M46)) | P45: 40 | Q45: =IF(P45="","",COUNTIFS($C$18:$C$2015,P$13,$D$18:$D$2015,">="&P45,$D$18:$D$2015,"<"&P46)) | S45: 70 | T45: =IF(S45="","",COUNTIFS($C$18:$C$2015,S$13,$D$18:$D$2015,">="&S45,$D$18:$D$2015,"<"&S46)) | V45: 70 | W45: =IF(V45="","",COUNTIFS($C$18:$C$2015,V$13,$D$18:$D$2015,">="&V45,$D$18:$D$2015,"<"&V46)) | Y45: 70 | Z45: =IF(Y45="","",COUNTIFS($C$18:$C$2015,Y$13,$D$18:$D$2015,">="&Y45,$D$18:$D$2015,"<"&Y46)) | AB45: 40 | AC45: =IF(AB45="","",COUNTIFS($C$18:$C$2015,AB$13,$D$18:$D$2015,">="&AB45,$D$18:$D$2015,"<"&AB46))
G46: 41 | H46: =IF(G46="","",COUNTIFS($C$18:$C$2015,G$13,$D$18:$D$2015,">="&G46,$D$18:$D$2015,"<"&G47)) | K46: =IF(J46="","",COUNTIFS($C$18:$C$2015,J$13,$D$18:$D$2015,">="&J46,$D$18:$D$2015,"<"&J47)) | M46: 72 | N46: =IF(M46="","",COUNTIFS($C$18:$C$2015,M$13,$D$18:$D$2015,">="&M46,$D$18:$D$2015,"<"&M47)) | P46: 41 | Q46: =IF(P46="","",COUNTIFS($C$18:$C$2015,P$13,$D$18:$D$2015,">="&P46,$D$18:$D$2015,"<"&P47)) | S46: 72 | T46: =IF(S46="","",COUNTIFS($C$18:$C$2015,S$13,$D$18:$D$2015,">="&S46,$D$18:$D$2015,"<"&S47)) | V46: 72 | W46: =IF(V46="","",COUNTIFS($C$18:$C$2015,V$13,$D$18:$D$2015,">="&V46,$D$18:$D$2015,"<"&V47)) | Y46: 72 | Z46: =IF(Y46="","",COUNTIFS($C$18:$C$2015,Y$13,$D$18:$D$2015,">="&Y46,$D$18:$D$2015,"<"&Y47)) | AB46: 41 | AC46: =IF(AB46="","",COUNTIFS($C$18:$C$2015,AB$13,$D$18:$D$2015,">="&AB46,$D$18:$D$2015,"<"&AB47))
G47: 42 | H47: =IF(G47="","",COUNTIFS($C$18:$C$2015,G$13,$D$18:$D$2015,">="&G47,$D$18:$D$2015,"<"&G48)) | K47: =IF(J47="","",COUNTIFS($C$18:$C$2015,J$13,$D$18:$D$2015,">="&J47,$D$18:$D$2015,"<"&J48)) | M47: 74 | N47: =IF(M47="","",COUNTIFS($C$18:$C$2015,M$13,$D$18:$D$2015,">="&M47,$D$18:$D$2015,"<"&M48)) | P47: 42 | Q47: =IF(P47="","",COUNTIFS($C$18:$C$2015,P$13,$D$18:$D$2015,">="&P47,$D$18:$D$2015,"<"&P48)) | S47: 74 | T47: =IF(S47="","",COUNTIFS($C$18:$C$2015,S$13,$D$18:$D$2015,">="&S47,$D$18:$D$2015,"<"&S48)) | V47: 74 | W47: =IF(V47="","",COUNTIFS($C$18:$C$2015,V$13,$D$18:$D$2015,">="&V47,$D$18:$D$2015,"<"&V48)) | Y47: 74 | Z47: =IF(Y47="","",COUNTIFS($C$18:$C$2015,Y$13,$D$18:$D$2015,">="&Y47,$D$18:$D$2015,"<"&Y48)) | AB47: 42 | AC47: =IF(AB47="","",COUNTIFS($C$18:$C$2015,AB$13,$D$18:$D$2015,">="&AB47,$D$18:$D$2015,"<"&AB48))
G48: 43 | H48: =IF(G48="","",COUNTIFS($C$18:$C$2015,G$13,$D$18:$D$2015,">="&G48,$D$18:$D$2015,"<"&G49)) | K48: =IF(J48="","",COUNTIFS($C$18:$C$2015,J$13,$D$18:$D$2015,">="&J48,$D$18:$D$2015,"<"&J49)) | M48: 76 | N48: =IF(M48="","",COUNTIFS($C$18:$C$2015,M$13,$D$18:$D$2015,">="&M48,$D$18:$D$2015,"<"&M49)) | P48: 43 | Q48: =IF(P48="","",COUNTIFS($C$18:$C$2015,P$13,$D$18:$D$2015,">="&P48,$D$18:$D$2015,"<"&P49)) | S48: 76 | T48: =IF(S48="","",COUNTIFS($C$18:$C$2015,S$13,$D$18:$D$2015,">="&S48,$D$18:$D$2015,"<"&S49)) | V48: 76 | W48: =IF(V48="","",COUNTIFS($C$18:$C$2015,V$13,$D$18:$D$2015,">="&V48,$D$18:$D$2015,"<"&V49)) | Y48: 76 | Z48: =IF(Y48="","",COUNTIFS($C$18:$C$2015,Y$13,$D$18:$D$2015,">="&Y48,$D$18:$D$2015,"<"&Y49)) | AB48: 43 | AC48: =IF(AB48="","",COUNTIFS($C$18:$C$2015,AB$13,$D$18:$D$2015,">="&AB48,$D$18:$D$2015,"<"&AB49))
G49: 44 | H49: =IF(G49="","",COUNTIFS($C$18:$C$2015,G$13,$D$18:$D$2015,">="&G49,$D$18:$D$2015,"<"&G50)) | K49: =IF(J49="","",COUNTIFS($C$18:$C$2015,J$13,$D$18:$D$2015,">="&J49,$D$18:$D$2015,"<"&J50)) | M49: 78 | N49: =IF(M49="","",COUNTIFS($C$18:$C$2015,M$13,$D$18:$D$2015,">="&M49,$D$18:$D$2015,"<"&M50)) | P49: 44 | Q49: =IF(P49="","",COUNTIFS($C$18:$C$2015,P$13,$D$18:$D$2015,">="&P49,$D$18:$D$2015,"<"&P50)) | S49: 78 | T49: =IF(S49="","",COUNTIFS($C$18:$C$2015,S$13,$D$18:$D$2015,">="&S49,$D$18:$D$2015,"<"&S50)) | V49: 78 | W49: =IF(V49="","",COUNTIFS($C$18:$C$2015,V$13,$D$18:$D$2015,">="&V49,$D$18:$D$2015,"<"&V50)) | Y49: 78 | Z49: =IF(Y49="","",COUNTIFS($C$18:$C$2015,Y$13,$D$18:$D$2015,">="&Y49,$D$18:$D$2015,"<"&Y50)) | AB49: 44 | AC49: =IF(AB49="","",COUNTIFS($C$18:$C$2015,AB$13,$D$18:$D$2015,">="&AB49,$D$18:$D$2015,"<"&AB50))
G50: 45 | H50: =IF(G50="","",COUNTIFS($C$18:$C$2015,G$13,$D$18:$D$2015,">="&G50,$D$18:$D$2015,"<"&G51)) | K50: =IF(J50="","",COUNTIFS($C$18:$C$2015,J$13,$D$18:$D$2015,">="&J50,$D$18:$D$2015,"<"&J51)) | M50: 80 | N50: =IF(M50="","",COUNTIFS($C$18:$C$2015,M$13,$D$18:$D$2015,">="&M50,$D$18:$D$2015,"<"&M51)) | P50: 45 | Q50: =IF(P50="","",COUNTIFS($C$18:$C$2015,P$13,$D$18:$D$2015,">="&P50,$D$18:$D$2015,"<"&P51)) | S50: 80 | T50: =IF(S50="","",COUNTIFS($C$18:$C$2015,S$13,$D$18:$D$2015,">="&S50,$D$18:$D$2015,"<"&S51)) | V50: 80 | W50: =IF(V50="","",COUNTIFS($C$18:$C$2015,V$13,$D$18:$D$2015,">="&V50,$D$18:$D$2015,"<"&V51)) | Y50: 80 | Z50: =IF(Y50="","",COUNTIFS($C$18:$C$2015,Y$13,$D$18:$D$2015,">="&Y50,$D$18:$D$2015,"<"&Y51)) | AB50: 45 | AC50: =IF(AB50="","",COUNTIFS($C$18:$C$2015,AB$13,$D$18:$D$2015,">="&AB50,$D$18:$D$2015,"<"&AB51))
G51: 46 | H51: =IF(G51="","",COUNTIFS($C$18:$C$2015,G$13,$D$18:$D$2015,">="&G51,$D$18:$D$2015,"<"&G52)) | K51: =IF(J51="","",COUNTIFS($C$18:$C$2015,J$13,$D$18:$D$2015,">="&J51,$D$18:$D$2015,"<"&J52)) | M51: 82 | N51: =IF(M51="","",COUNTIFS($C$18:$C$2015,M$13,$D$18:$D$2015,">="&M51,$D$18:$D$2015,"<"&M52)) | P51: 46 | Q51: =IF(P51="","",COUNTIFS($C$18:$C$2015,P$13,$D$18:$D$2015,">="&P51,$D$18:$D$2015,"<"&P52)) | S51: 82 | T51: =IF(S51="","",COUNTIFS($C$18:$C$2015,S$13,$D$18:$D$2015,">="&S51,$D$18:$D$2015,"<"&S52)) | W51: =IF(V51="","",COUNTIFS($C$18:$C$2015,V$13,$D$18:$D$2015,">="&V51,$D$18:$D$2015,"<"&V52)) | Z51: =IF(Y51="","",COUNTIFS($C$18:$C$2015,Y$13,$D$18:$D$2015,">="&Y51,$D$18:$D$2015,"<"&Y52)) | AB51: 46 | AC51: =IF(AB51="","",COUNTIFS($C$18:$C$2015,AB$13,$D$18:$D$2015,">="&AB51,$D$18:$D$2015,"<"&AB52))
G52: 47 | H52: =IF(G52="","",COUNTIFS($C$18:$C$2015,G$13,$D$18:$D$2015,">="&G52,$D$18:$D$2015,"<"&G53)) | K52: =IF(J52="","",COUNTIFS($C$18:$C$2015,J$13,$D$18:$D$2015,">="&J52,$D$18:$D$2015,"<"&J53)) | M52: 84 | N52: =IF(M52="","",COUNTIFS($C$18:$C$2015,M$13,$D$18:$D$2015,">="&M52,$D$18:$D$2015,"<"&M53)) | P52: 47 | Q52: =IF(P52="","",COUNTIFS($C$18:$C$2015,P$13,$D$18:$D$2015,">="&P52,$D$18:$D$2015,"<"&P53)) | S52: 84 | T52: =IF(S52="","",COUNTIFS($C$18:$C$2015,S$13,$D$18:$D$2015,">="&S52,$D$18:$D$2015,"<"&S53)) | W52: =IF(V52="","",COUNTIFS($C$18:$C$2015,V$13,$D$18:$D$2015,">="&V52,$D$18:$D$2015,"<"&V53)) | Z52: =IF(Y52="","",COUNTIFS($C$18:$C$2015,Y$13,$D$18:$D$2015,">="&Y52,$D$18:$D$2015,"<"&Y53)) | AB52: 47 | AC52: =IF(AB52="","",COUNTIFS($C$18:$C$2015,AB$13,$D$18:$D$2015,">="&AB52,$D$18:$D$2015,"<"&AB53))
G53: 48 | H53: =IF(G53="","",COUNTIFS($C$18:$C$2015,G$13,$D$18:$D$2015,">="&G53,$D$18:$D$2015,"<"&G54)) | K53: =IF(J53="","",COUNTIFS($C$18:$C$2015,J$13,$D$18:$D$2015,">="&J53,$D$18:$D$2015,"<"&J54)) | M53: 86 | N53: =IF(M53="","",COUNTIFS($C$18:$C$2015,M$13,$D$18:$D$2015,">="&M53,$D$18:$D$2015,"<"&M54)) | P53: 48 | Q53: =IF(P53="","",COUNTIFS($C$18:$C$2015,P$13,$D$18:$D$2015,">="&P53,$D$18:$D$2015,"<"&P54)) | S53: 86 | T53: =IF(S53="","",COUNTIFS($C$18:$C$2015,S$13,$D$18:$D$2015,">="&S53,$D$18:$D$2015,"<"&S54)) | W53: =IF(V53="","",COUNTIFS($C$18:$C$2015,V$13,$D$18:$D$2015,">="&V53,$D$18:$D$2015,"<"&V54)) | Z53: =IF(Y53="","",COUNTIFS($C$18:$C$2015,Y$13,$D$18:$D$2015,">="&Y53,$D$18:$D$2015,"<"&Y54)) | AB53: 48 | AC53: =IF(AB53="","",COUNTIFS($C$18:$C$2015,AB$13,$D$18:$D$2015,">="&AB53,$D$18:$D$2015,"<"&AB54))
G54: 49 | H54: =IF(G54="","",COUNTIFS($C$18:$C$2015,G$13,$D$18:$D$2015,">="&G54,$D$18:$D$2015,"<"&G55)) | K54: =IF(J54="","",COUNTIFS($C$18:$C$2015,J$13,$D$18:$D$2015,">="&J54,$D$18:$D$2015,"<"&J55)) | M54: 88 | N54: =IF(M54="","",COUNTIFS($C$18:$C$2015,M$13,$D$18:$D$2015,">="&M54,$D$18:$D$2015,"<"&M55)) | P54: 49 | Q54: =IF(P54="","",COUNTIFS($C$18:$C$2015,P$13,$D$18:$D$2015,">="&P54,$D$18:$D$2015,"<"&P55)) | S54: 88 | T54: =IF(S54="","",COUNTIFS($C$18:$C$2015,S$13,$D$18:$D$2015,">="&S54,$D$18:$D$2015,"<"&S55)) | W54: =IF(V54="","",COUNTIFS($C$18:$C$2015,V$13,$D$18:$D$2015,">="&V54,$D$18:$D$2015,"<"&V55)) | Z54: =IF(Y54="","",COUNTIFS($C$18:$C$2015,Y$13,$D$18:$D$2015,">="&Y54,$D$18:$D$2015,"<"&Y55)) | AB54: 49 | AC54: =IF(AB54="","",COUNTIFS($C$18:$C$2015,AB$13,$D$18:$D$2015,">="&AB54,$D$18:$D$2015,"<"&AB55))
G55: 50 | H55: =IF(G55="","",COUNTIFS($C$18:$C$2015,G$13,$D$18:$D$2015,">="&G55,$D$18:$D$2015,"<"&G56)) | K55: =IF(J55="","",COUNTIFS($C$18:$C$2015,J$13,$D$18:$D$2015,">="&J55,$D$18:$D$2015,"<"&J56)) | M55: 90 | N55: =IF(M55="","",COUNTIFS($C$18:$C$2015,M$13,$D$18:$D$2015,">="&M55,$D$18:$D$2015,"<"&M56)) | P55: 50 | Q55: =IF(P55="","",COUNTIFS($C$18:$C$2015,P$13,$D$18:$D$2015,">="&P55,$D$18:$D$2015,"<"&P56)) | S55: 90 | T55: =IF(S55="","",COUNTIFS($C$18:$C$2015,S$13,$D$18:$D$2015,">="&S55,$D$18:$D$2015,"<"&S56)) | W55: =IF(V55="","",COUNTIFS($C$18:$C$2015,V$13,$D$18:$D$2015,">="&V55,$D$18:$D$2015,"<"&V56)) | Z55: =IF(Y55="","",COUNTIFS($C$18:$C$2015,Y$13,$D$18:$D$2015,">="&Y55,$D$18:$D$2015,"<"&Y56)) | AB55: 50 | AC55: =IF(AB55="","",COUNTIFS($C$18:$C$2015,AB$13,$D$18:$D$2015,">="&AB55,$D$18:$D$2015,"<"&AB56))
...

Sheet M-03
G1: =FAO!B1&" max =" | H1: =+FAO!B10 | J1: =FAO!E1&" max =" | K1: =+FAO!E10 | M1: =FAO!H1&" max =" | N1: =+FAO!H10 | P1: =FAO!K1&" max =" | Q1: =+FAO!K10 | S1: =FAO!N1&" max =" | T1: =+FAO!N10 | V1: =FAO!Q1&" max =" | W1: =+FAO!Q10 | Y1: =FAO!T1&" max =" | Z1: =+FAO!T10 | AB1: =FAO!W1&" max =" | AC1: =+FAO!W10 | AE1: =COUNTA($C$15:$C$10001)
G2: obs n = | H2: =COUNTIF($C$18:$C$1003,G13) | J2: obs n = | K2: =COUNTIF($C$18:$C$1003,J13) | M2: obs n = | N2: =COUNTIF($C$18:$C$1003,M13) | P2: obs n = | Q2: =COUNTIF($C$18:$C$1003,P13) | S2: obs n = | T2: =COUNTIF($C$18:$C$1003,S13) | V2: obs n = | W2: =COUNTIF($C$18:$C$1003,V13) | Y2: obs n = | Z2: =COUNTIF($C$18:$C$1003,Y13) | AB2: obs n = | AC2: =COUNTIF($C$18:$C$1003,AB13)
G3: freq n= | H3: =+SUM(H15:H1003) | J3: freq n= | K3: =+SUM(K15:K1003) | M3: freq n= | N3: =+SUM(N15:N1003) | P3: freq n= | Q3: =+SUM(Q15:Q1003) | S3: freq n= | T3: =+SUM(T15:T1003) | V3: freq n= | W3: =+SUM(W15:W1003) | Y3: freq n= | Z3: =+SUM(Z15:Z1003) | AB3: freq n= | AC3: =+SUM(AC15:AC1003)
G4: first bin = | H4: 10 | J4: first bin = | K4: 10 | M4: first bin = | N4: 10 | P4: first bin = | Q4: 10 | S4: first bin = | T4: 10 | V4: first bin = | W4: 10 | Y4: first bin = | Z4: 10 | AB4: first bin = | AC4: 10
G5: increment = | H5: =+FAO!B14 | J5: increment = | K5: =+FAO!E14 | M5: increment = | N5: =+FAO!H14 | P5: increment = | Q5: =+FAO!K14 | S5: increment = | T5: =+FAO!N14 | V5: increment = | W5: =+FAO!Q14 | Y5: increment = | Z5: =+FAO!T14 | AB5: increment = | AC5: =+FAO!W14
G6: Complete = | H6: =COUNTIFS($C$18:$C$2015,G$13,$D$18:$D$2015,">5")/COUNTIF($C$18:$C$2015,G$13)*100 | J6: Complete = | K6: =COUNTIFS($C$18:$C$2015,J$13,$D$18:$D$2015,">5")/COUNTIF($C$18:$C$2015,J$13)*100 | M6: Complete = | N6: =COUNTIFS($C$18:$C$2015,M$13,$D$18:$D$2015,">5")/COUNTIF($C$18:$C$2015,M$13)*100 | P6: Complete = | Q6: =COUNTIFS($C$18:$C$2015,P$13,$D$18:$D$2015,">5")/COUNTIF($C$18:$C$2015,P$13)*100 | S6: Complete = | T6: =COUNTIFS($C$18:$C$2015,S$13,$D$18:$D$2015,">5")/COUNTIF($C$18:$C$2015,S$13)*100 | V6: Complete = | W6: =COUNTIFS($C$18:$C$2015,V$13,$D$18:$D$2015,">5")/COUNTIF($C$18:$C$2015,V$13)*100 | Y6: Complete = | Z6: =COUNTIFS($C$18:$C$2015,Y$13,$D$18:$D$2015,">5")/COUNTIF($C$18:$C$2015,Y$13)*100 | AB6: Complete = | AC6: =COUNTIFS($C$18:$C$2015,AB$13,$D$18:$D$2015,">5")/COUNTIF($C$18:$C$2015,AB$13)*100
G7: L50 (cm) = | H7: =+FAO!B11 | J7: L50 (cm) = | K7: =+FAO!E11 | M7: L50 (cm) = | N7: =+FAO!H11 | P7: L50 (cm) = | Q7: =+FAO!K11 | S7: L50 (cm) = | T7: =+FAO!N11 | V7: L50 (cm) = | W7: =+FAO!Q11 | Y7: L50 (cm) = | Z7: =+FAO!T11 | AB7: L50 (cm) = | AC7: =+FAO!W11
G8: Juven. (%) = | H8: =+ROUND(COUNTIFS($C$18:$C$2015,G$13,$D$18:$D$2015,"<"&H7)/COUNTIF($C$18:$C$2015,G$13)*100,0) | J8: Juven. (%) = | K8: =+ROUND(COUNTIFS($C$18:$C$2015,J$13,$D$18:$D$2015,"<"&K7)/COUNTIF($C$18:$C$2015,J$13)*100,0) | M8: Juven. (%) = | N8: =+ROUND(COUNTIFS($C$18:$C$2015,M$13,$D$18:$D$2015,"<"&N7)/COUNTIF($C$18:$C$2015,M$13)*100,0) | P8: Juven. (%) = | Q8: =+ROUND(COUNTIFS($C$18:$C$2015,P$13,$D$18:$D$2015,"<"&Q7)/COUNTIF($C$18:$C$2015,P$13)*100,0) | S8: Juven. (%) = | T8: =+ROUND(COUNTIFS($C$18:$C$2015,S$13,$D$18:$D$2015,"<"&T7)/COUNTIF($C$18:$C$2015,S$13)*100,0) | V8: Juven. (%) = | W8: =+ROUND(COUNTIFS($C$18:$C$2015,V$13,$D$18:$D$2015,"<"&W7)/COUNTIF($C$18:$C$2015,V$13)*100,0) | Y8: Juven. (%) = | Z8: =+ROUND(COUNTIFS($C$18:$C$2015,Y$13,$D$18:$D$2015,"<"&Z7)/COUNTIF($C$18:$C$2015,Y$13)*100,0) | AB8: Juven. (%) = | AC8: =+ROUND(COUNTIFS($C$18:$C$2015,AB$13,$D$18:$D$2015,"<"&AC7)/COUNTIF($C$18:$C$2015,AB$13)*100,0)
G9: =+FAO!B6 | J9: =+FAO!E6 | M9: =+FAO!H6 | P9: =+FAO!K6 | S9: =+FAO!N6 | V9: =+FAO!Q6 | Y9: =+FAO!T6 | AB9: =+FAO!W6
G10: =+FAO!B7 | J10: =+FAO!E7 | M10: =+FAO!H7 | P10: =+FAO!K7 | S10: =+FAO!N7 | V10: =+FAO!Q7 | Y10: =+FAO!T7 | AB10: =+FAO!W7
G11: =+FAO!B9 | J11: =+FAO!E9 | M11: =+FAO!H9 | P11: =+FAO!K9 | S11: =+FAO!N9 | V11: =+FAO!Q9 | Y11: =+FAO!T9 | AB11: =+FAO!W9
G12: =+FAO!B5 | J12: =+FAO!E5 | M12: =+FAO!H5 | P12: =+FAO!K5 | S12: =+FAO!N5 | V12: =+FAO!Q5 | Y12: =+FAO!T5 | AB12: =+FAO!W5
D13: #VALUE! | E13: =COUNTA(C15:C1003) | G13: =+FAO!B1 | H13: =+FAO!B3 | J13: =+FAO!E1 | K13: =+FAO!E3 | M13: =+FAO!H1 | N13: =+FAO!H3 | P13: =+FAO!K1 | Q13: =+FAO!K3 | S13: =+FAO!N1 | T13: =+FAO!N3 | V13: =+FAO!Q1 | W13: =+FAO!Q3 | Y13: =+FAO!T1 | Z13: =+FAO!T3 | AB13: =+FAO!W1 | AC13: =+FAO!W3
A14: TRIP | B14: DATE | C14: FAO | D14: OBS | E14: ID | G14: ="LC-"&G13 | H14: ="FQ-"&G13 | J14: ="LC-"&J13 | K14: ="FQ-"&J13 | M14: ="LC-"&M13 | N14: ="FQ-"&M13 | P14: ="LC-"&P13 | Q14: ="FQ-"&P13 | S14: ="LC-"&S13 | T14: ="FQ-"&S13 | V14: ="LC-"&V13 | W14: ="FQ-"&V13 | Y14: ="LC-"&Y13 | Z14: ="FQ-"&Y13 | AB14: ="LC-"&AB13 | AC14: ="FQ-"&AB13
